Workbook

Sheet راهنما
A1: محاسبهٔ وزن‌ها به روش فرایند تحلیل سلسله‌مراتبی (AHP) با مقایسهٔ زوجی — نسخهٔ ماتریس‌های برآوردی
A2: پژوهش: شناسایی و اولویت‌بندی چالش‌های فروش در شرکت‌های تک‌محصولی فعال در صنعت مواد غذایی
B4: توجه: ماتریس‌های این فایل برآوردی‌اند: از امتیازهای دور سوم دلفی هر خبره ساخته شده‌اند و پاسخ مستقیم خبرگان به مقایسه‌های زوجی نیستند. قاعدهٔ برآورد: برای هر دو مورد، اختلاف امتیاز دور سوم (برای مؤلفه‌ها، میانگین امتیاز گویه‌های آن) محاسبه شد؛ اختلاف کمتر از ۰٫۵ برابر (۱) و در غیر این صورت شدت برتری ۱ + ⌈اختلاف⌉ گرفته شد. به همین دلیل نرخ ناسازگاری (CR) این فایل فقط سازگاری درونی قاعدهٔ تبدیل را نشان می‌دهد و ملاک اعتبار قضاوت خبرگان نیست.
B6: ۱. این فایل چه کاری می‌کند؟
B7: پاسخ‌های مقایسهٔ زوجی هفت خبره را، که روی پرسشنامهٔ مقایسهٔ زوجی (فایل Word همراه) علامت زده‌اند، به وزن مؤلفه‌ها و گویه‌ها تبدیل می‌کند، نرخ ناسازگاری (CR) هر خبره را می‌سنجد و وزن‌های نهایی را با وزن‌دهی مستقیم فعلی پایان‌نامه مقایسه می‌کند. فقط برگهٔ «ورودی» را پر کنید؛ همهٔ برگه‌های دیگر با فرمول محاسبه می‌شوند و نیازی به دست‌کاری ندارند.
B9: ۲. مراحل کار
B10: ۱) پاسخ هر خبره را از پرسشنامهٔ تکمیل‌شده در یک ستون از برگهٔ «ورودی» (ستون‌های خ۱ تا خ۷) وارد کنید. شمارهٔ ردیف‌ها با شمارهٔ ردیف‌های پرسشنامه یکی است (۱ تا ۷۰). نحوهٔ کدگذاری در بخش ۳ آمده است.
B11: ۲) برگهٔ «سازگاری» را ببینید. اگر نرخ ناسازگاری (CR) ماتریسی از حد مجاز بیشتر باشد (قرمز)، آن ماتریس را با همان خبره مرور کنید. در برگهٔ هر خبره (خ۱ تا خ۷)، سمت چپ هر ماتریس، مقایسه‌ای که بیشترین انحراف را از وزن‌های برآوردشده دارد با رنگ قرمز مشخص شده است؛ نخست همان را با خبره مرور کنید. پس از اصلاح، عدد جدید را در برگهٔ «ورودی» جایگزین کنید.
B12: ۳) وقتی پاسخ هر هفت خبره کامل و سازگار شد، برگهٔ «نتیجه» وزن نهایی مؤلفه‌ها و گویه‌ها را نشان می‌دهد؛ تا آن زمان نتایج موقت است و بالای برگه این موضوع نوشته می‌شود.
B13: ۴) ستون‌های «روش مستقیم» در برگهٔ «نتیجه» وزن‌های فعلی پایان‌نامه‌اند (میانگین امتیاز دور سوم دلفی تقسیم بر مجموع میانگین‌ها). ضریب همبستگی اسپیرمن در پایین برگه نشان می‌دهد دو رتبه‌بندی چقدر همسو هستند.
B15: ۳. کدگذاری پاسخ‌ها در برگهٔ «ورودی»
B16: در پرسشنامه علامت زده شده است | C16: در خانه بنویسید | D16: معنی
B17: عدد k از ۲ تا ۹، در سمت «الف» (سمت راست) | C17: k | D17: مورد «الف» k برابر مهم‌تر از مورد «ب» است (مثلاً 3: سه برابر).
B18: عدد ۱ (ستون میانی) | C18: 1 | D18: دو مورد اهمیت برابر دارند.
B19: عدد k از ۲ تا ۹، در سمت «ب» (سمت چپ) | C19: -k | D19: مورد «ب» k برابر مهم‌تر از مورد «الف» است (مثلاً -3: سه برابر).
B21: مثال: ردیف ۳۸ پرسشنامه گ۱ را با گ۳ مقایسه می‌کند. اگر خبرهٔ ۲ عدد ۴ را در سمت «ب» علامت زده باشد، یعنی گ۳ چهار برابر مهم‌تر از گ۱ است. در این صورت در برگهٔ «ورودی»، ردیف ۳۸، ستون «خ۲» عدد منفی چهار نوشته می‌شود (جدول نمونهٔ زیر؛ این جدول فقط نمونه است و در محاسبه نقشی ندارد).
B22: ردیف پرسشنامه | C22: خبره | D22: علامت زده‌شده | E22: عددی که وارد می‌شود
B23: 38 | C23: خ۲ | D23: عدد ۴ در سمت «ب» | E23: -4
B25: ۴. پارامترها
B26: حد مجاز نرخ ناسازگاری (CR) | C26: 0.1 | D26: اگر CR بیشتر از این عدد باشد، ماتریس ناسازگار است و باید با خبره مرور شود (Saaty, 1980).
B28: تعداد گزینه‌های ماتریس (n) | C28: RI
B29: 1 | C29: 0
B30: 2 | C30: 0
B31: 3 | C31: 0.58
B32: 4 | C32: 0.9
B33: 5 | C33: 1.12
B34: 6 | C34: 1.24
B35: 7 | C35: 1.32
B36: 8 | C36: 1.41
B37: 9 | C37: 1.45
B38: 10 | C38: 1.49
B40: ۵. روش محاسبه (خلاصه)
B41: • هر پاسخ به نسبت اهمیت تبدیل می‌شود: عدد مثبت همان عدد می‌ماند، عدد ۱ همان ۱ می‌ماند و عدد منفی به معکوس قدرمطلق خود تبدیل می‌شود (مثلاً منفی سه به یک‌سوم). نسبت‌های پایین قطر ماتریس معکوس نسبت‌های بالای قطرند.
B42: • ساختار سلسله‌مراتبی: هدف ← ۹ مؤلفه ← ۲۹ گویه. یک ماتریس ۹×۹ برای مؤلفه‌ها و نُه ماتریس کوچک برای گویه‌های درون هر مؤلفه ساخته می‌شود (۳۶ + ۳۴ = ۷۰ مقایسه برای هر خبره).
B43: • وزن هر ماتریس: میانگین هندسی عددهای هر سطر، سپس تقسیم بر مجموع این میانگین‌ها (روش میانگین هندسی سطرها، معادل کمترین مربعات لگاریتمی؛ Crawford & Williams, 1985).
B44: • ترکیب نظر خبرگان: داوری هر مقایسه از میانگین هندسی داوری‌های خبرگان به دست می‌آید (Aczél & Saaty, 1983) و با آن ماتریس‌های تجمیعی ساخته می‌شود.
B45: • مقایسهٔ دارای بیشترین انحراف: نسبت داوری‌شده با نسبت وزن‌های برآوردشدهٔ همان دو مورد سنجیده می‌شود؛ هرچه این انحراف از ۱ دورتر باشد، آن داوری با بقیهٔ داوری‌های خبره ناهماهنگ‌تر است.
B46: • اگر خبره‌ای فقط بخشی از ردیف‌ها را پاسخ داده باشد، ماتریس‌های ناقص او محاسبه نمی‌شوند (وضعیت «ناقص»)؛ ماتریس تجمیعی از خبرگانی ساخته می‌شود که آن مقایسه را پاسخ داده‌اند.
B48: فرمول‌های اصلی | D48: توضیح
B49: w(i) = GM(i) / Σ GM | D49: وزن مورد i: میانگین هندسی سطر i تقسیم بر مجموع میانگین‌های هندسی همهٔ سطرها.
...

Sheet ورودی
A1: ورودی: ماتریس‌های برآوردی از امتیازهای دور سوم (نه پاسخ مستقیم خبرگان)
A2: هر ردیف یک مقایسه از پرسشنامه است. برای هر خبره عدد را در ستون او بنویسید: k (۲ تا ۹) اگر «الف» مهم‌تر است، 1 اگر برابرند، و -k اگر «ب» مهم‌تر است (جزئیات و مثال در برگهٔ «راهنما»). خانه‌های بی‌پاسخ را خالی بگذارید.
D4: تعداد پاسخ ثبت‌شده (از ۷۰) | G4: =COUNT(G9:G78) -> 70 | H4: =COUNT(H9:H78) -> 70 | I4: =COUNT(I9:I78) -> 70 | J4: =COUNT(J9:J78) -> 70 | K4: =COUNT(K9:K78) -> 70 | L4: =COUNT(L9:L78) -> 70 | M4: =COUNT(M9:M78) -> 70
D5: وضعیت | G5: =IF(G4=0,"—",IF(G4=70,"کامل","ناقص")) -> کامل | H5: =IF(H4=0,"—",IF(H4=70,"کامل","ناقص")) -> کامل | I5: =IF(I4=0,"—",IF(I4=70,"کامل","ناقص")) -> کامل | J5: =IF(J4=0,"—",IF(J4=70,"کامل","ناقص")) -> کامل | K5: =IF(K4=0,"—",IF(K4=70,"کامل","ناقص")) -> کامل | L5: =IF(L4=0,"—",IF(L4=70,"کامل","ناقص")) -> کامل | M5: =IF(M4=0,"—",IF(M4=70,"کامل","ناقص")) -> کامل
A8: ردیف | B8: بخش | C8: کد الف | D8: مورد الف | E8: کد ب | F8: مورد ب | G8: خ۱ | H8: خ۲ | I8: خ۳ | J8: خ۴ | K8: خ۵ | L8: خ۶ | M8: خ۷ | N8: تعداد پاسخ‌دهنده
A9: 1 | B9: الف | C9: م۱ | D9: آسیب‌پذیری ساختاری ناشی از تمرکز بر محصول واحد | E9: م۲ | F9: ضعف برندسازی و دشواری تمایز محصول | G9: 2 | H9: 2 | I9: 3 | J9: 2 | K9: 1 | L9: 2 | M9: 2 | N9: =COUNT(G9:M9) -> 7
A10: 2 | B10: الف | C10: م۱ | D10: آسیب‌پذیری ساختاری ناشی از تمرکز بر محصول واحد | E10: م۳ | F10: دشواری جذب و حفظ مشتری و وفاداری پایین | G10: 2 | H10: 2 | I10: 2 | J10: 2 | K10: 1 | L10: 1 | M10: 1 | N10: =COUNT(G10:M10) -> 7
A11: 3 | B11: الف | C11: م۱ | D11: آسیب‌پذیری ساختاری ناشی از تمرکز بر محصول واحد | E11: م۴ | F11: ضعف در برنامه‌ریزی، پیش‌بینی و مدیریت فروش | G11: 2 | H11: 2 | I11: 2 | J11: 2 | K11: 1 | L11: 1 | M11: 1 | N11: =COUNT(G11:M11) -> 7
A12: 4 | B12: الف | C12: م۱ | D12: آسیب‌پذیری ساختاری ناشی از تمرکز بر محصول واحد | E12: م۵ | F12: ناکارآمدی و هزینه‌بری شبکه توزیع و فروش | G12: 1 | H12: 2 | I12: 1 | J12: 1 | K12: 1 | L12: 1 | M12: 1 | N12: =COUNT(G12:M12) -> 7
A13: 5 | B13: الف | C13: م۱ | D13: آسیب‌پذیری ساختاری ناشی از تمرکز بر محصول واحد | E13: م۶ | F13: شدت رقابت و فشار قیمتی بازار | G13: 1 | H13: 1 | I13: 1 | J13: 1 | K13: 1 | L13: 1 | M13: 1 | N13: =COUNT(G13:M13) -> 7
A14: 6 | B14: الف | C14: م۱ | D14: آسیب‌پذیری ساختاری ناشی از تمرکز بر محصول واحد | E14: م۷ | F14: تغییر ذائقه مصرف‌کننده و محدودیت بازار هدف | G14: 1 | H14: 1 | I14: 1 | J14: 1 | K14: 1 | L14: 1 | M14: 1 | N14: =COUNT(G14:M14) -> 7
A15: 7 | B15: الف | C15: م۱ | D15: آسیب‌پذیری ساختاری ناشی از تمرکز بر محصول واحد | E15: م۸ | F15: ناپایداری تأمین و نوسان بهای مواد اولیه | G15: 1 | H15: 1 | I15: 2 | J15: 1 | K15: 1 | L15: 1 | M15: 1 | N15: =COUNT(G15:M15) -> 7
A16: 8 | B16: الف | C16: م۱ | D16: آسیب‌پذیری ساختاری ناشی از تمرکز بر محصول واحد | E16: م۹ | F16: فشارهای اقتصاد کلان و کاهش قدرت خرید | G16: 1 | H16: 1 | I16: 1 | J16: 1 | K16: -2 | L16: -2 | M16: -2 | N16: =COUNT(G16:M16) -> 7
A17: 9 | B17: الف | C17: م۲ | D17: ضعف برندسازی و دشواری تمایز محصول | E17: م۳ | F17: دشواری جذب و حفظ مشتری و وفاداری پایین | G17: 1 | H17: 1 | I17: -2 | J17: 1 | K17: 1 | L17: 1 | M17: 1 | N17: =COUNT(G17:M17) -> 7
A18: 10 | B18: الف | C18: م۲ | D18: ضعف برندسازی و دشواری تمایز محصول | E18: م۴ | F18: ضعف در برنامه‌ریزی، پیش‌بینی و مدیریت فروش | G18: 1 | H18: 1 | I18: 1 | J18: 1 | K18: 1 | L18: -2 | M18: 1 | N18: =COUNT(G18:M18) -> 7
A19: 11 | B19: الف | C19: م۲ | D19: ضعف برندسازی و دشواری تمایز محصول | E19: م۵ | F19: ناکارآمدی و هزینه‌بری شبکه توزیع و فروش | G19: -2 | H19: 1 | I19: -2 | J19: -2 | K19: -2 | L19: -2 | M19: -2 | N19: =COUNT(G19:M19) -> 7
A20: 12 | B20: الف | C20: م۲ | D20: ضعف برندسازی و دشواری تمایز محصول | E20: م۶ | F20: شدت رقابت و فشار قیمتی بازار | G20: -2 | H20: -2 | I20: -2 | J20: -2 | K20: -2 | L20: -2 | M20: -2 | N20: =COUNT(G20:M20) -> 7
... A78: 70 | B78: ب | C78: گ۲۸ | D78: افزایش بهای تمام‌شده و فشار بر حاشیه سود | E78: گ۲۹ | F78: کاهش قدرت خرید و مشکلات اقتصادی مصرف‌کننده | G78: 2 | H78: 2 | I78: 2 | J78: 2 | K78: 2 | L78: 2 | M78: 2 | N78: =COUNT(G78:M78) -> 7

Sheet سازگاری
A1: سازگاری: نرخ ناسازگاری (CR) هر ماتریس برای هر خبره و برای ماتریس تجمیعی
A2: هر خانه نرخ ناسازگاری (CR) یک ماتریس است. قرمز: بیشتر از حد مجاز، باید با خبره مرور شود؛ سبز: سازگار؛ «ناقص»: هنوز همهٔ مقایسه‌های آن ماتریس ثبت نشده است. ماتریس‌های دو گزینه‌ای همیشه سازگارند (CR = 0).
B3: حد مجاز CR | C3: =راهنما!$C$26 -> 0.1
A5: شمارهٔ ماتریس | B5: ماتریس | C5: n | D5: خ۱ | E5: خ۲ | F5: خ۳ | G5: خ۴ | H5: خ۵ | I5: خ۶ | J5: خ۷ | K5: تجمیعی
A6: 1 | B6: مؤلفه‌ها (۹×۹) | C6: 9 | D6: =IF(خ۱!P13="ناقص","ناقص",خ۱!P12) -> 0.0085063885 | E6: =IF(خ۲!P13="ناقص","ناقص",خ۲!P12) -> 0.0098358951 | F6: =IF(خ۳!P13="ناقص","ناقص",خ۳!P12) -> 0.011491022 | G6: =IF(خ۴!P13="ناقص","ناقص",خ۴!P12) -> 0.0085063885 | H6: =IF(خ۵!P13="ناقص","ناقص",خ۵!P12) -> 0.012825626 | I6: =IF(خ۶!P13="ناقص","ناقص",خ۶!P12) -> 0.012690686 | J6: =IF(خ۷!P13="ناقص","ناقص",خ۷!P12) -> 0.012122752 | K6: =IF(تجمیع!P13="ناقص","ناقص",تجمیع!P12) -> 0.0022940953
A7: 2 | B7: گویه‌های م۱: آسیب‌پذیری ساختاری ناشی از تمرکز بر محصول واحد | C7: 3 | D7: =IF(خ۱!P27="ناقص","ناقص",خ۱!P26) -> 0 | E7: =IF(خ۲!P27="ناقص","ناقص",خ۲!P26) -> 0 | F7: =IF(خ۳!P27="ناقص","ناقص",خ۳!P26) -> 0 | G7: =IF(خ۴!P27="ناقص","ناقص",خ۴!P26) -> 0 | H7: =IF(خ۵!P27="ناقص","ناقص",خ۵!P26) -> 0 | I7: =IF(خ۶!P27="ناقص","ناقص",خ۶!P26) -> 0 | J7: =IF(خ۷!P27="ناقص","ناقص",خ۷!P26) -> 0 | K7: =IF(تجمیع!P27="ناقص","ناقص",تجمیع!P26) -> 0
A8: 3 | B8: گویه‌های م۲: ضعف برندسازی و دشواری تمایز محصول | C8: 4 | D8: =IF(خ۱!P39="ناقص","ناقص",خ۱!P38) -> 0 | E8: =IF(خ۲!P39="ناقص","ناقص",خ۲!P38) -> 0 | F8: =IF(خ۳!P39="ناقص","ناقص",خ۳!P38) -> 0 | G8: =IF(خ۴!P39="ناقص","ناقص",خ۴!P38) -> 0 | H8: =IF(خ۵!P39="ناقص","ناقص",خ۵!P38) -> 0 | I8: =IF(خ۶!P39="ناقص","ناقص",خ۶!P38) -> 0 | J8: =IF(خ۷!P39="ناقص","ناقص",خ۷!P38) -> 0 | K8: =IF(تجمیع!P39="ناقص","ناقص",تجمیع!P38) -> 0
A9: 4 | B9: گویه‌های م۳: دشواری جذب و حفظ مشتری و وفاداری پایین | C9: 3 | D9: =IF(خ۱!P51="ناقص","ناقص",خ۱!P50) -> 0 | E9: =IF(خ۲!P51="ناقص","ناقص",خ۲!P50) -> 0 | F9: =IF(خ۳!P51="ناقص","ناقص",خ۳!P50) -> 0 | G9: =IF(خ۴!P51="ناقص","ناقص",خ۴!P50) -> 0 | H9: =IF(خ۵!P51="ناقص","ناقص",خ۵!P50) -> 0 | I9: =IF(خ۶!P51="ناقص","ناقص",خ۶!P50) -> 0 | J9: =IF(خ۷!P51="ناقص","ناقص",خ۷!P50) -> 0 | K9: =IF(تجمیع!P51="ناقص","ناقص",تجمیع!P50) -> 0
A10: 5 | B10: گویه‌های م۴: ضعف در برنامه‌ریزی، پیش‌بینی و مدیریت فروش | C10: 4 | D10: =IF(خ۱!P63="ناقص","ناقص",خ۱!P62) -> 0 | E10: =IF(خ۲!P63="ناقص","ناقص",خ۲!P62) -> 0 | F10: =IF(خ۳!P63="ناقص","ناقص",خ۳!P62) -> 0 | G10: =IF(خ۴!P63="ناقص","ناقص",خ۴!P62) -> 0 | H10: =IF(خ۵!P63="ناقص","ناقص",خ۵!P62) -> 0 | I10: =IF(خ۶!P63="ناقص","ناقص",خ۶!P62) -> 0 | J10: =IF(خ۷!P63="ناقص","ناقص",خ۷!P62) -> 0 | K10: =IF(تجمیع!P63="ناقص","ناقص",تجمیع!P62) -> 0
A11: 6 | B11: گویه‌های م۵: ناکارآمدی و هزینه‌بری شبکه توزیع و فروش | C11: 4 | D11: =IF(خ۱!P75="ناقص","ناقص",خ۱!P74) -> 0 | E11: =IF(خ۲!P75="ناقص","ناقص",خ۲!P74) -> 0 | F11: =IF(خ۳!P75="ناقص","ناقص",خ۳!P74) -> 0 | G11: =IF(خ۴!P75="ناقص","ناقص",خ۴!P74) -> 0 | H11: =IF(خ۵!P75="ناقص","ناقص",خ۵!P74) -> 0 | I11: =IF(خ۶!P75="ناقص","ناقص",خ۶!P74) -> 0 | J11: =IF(خ۷!P75="ناقص","ناقص",خ۷!P74) -> 0 | K11: =IF(تجمیع!P75="ناقص","ناقص",تجمیع!P74) -> 0
A12: 7 | B12: گویه‌های م۶: شدت رقابت و فشار قیمتی بازار | C12: 3 | D12: =IF(خ۱!P87="ناقص","ناقص",خ۱!P86) -> 0 | E12: =IF(خ۲!P87="ناقص","ناقص",خ۲!P86) -> 0 | F12: =IF(خ۳!P87="ناقص","ناقص",خ۳!P86) -> 0 | G12: =IF(خ۴!P87="ناقص","ناقص",خ۴!P86) -> 0 | H12: =IF(خ۵!P87="ناقص","ناقص",خ۵!P86) -> 0 | I12: =IF(خ۶!P87="ناقص","ناقص",خ۶!P86) -> 0 | J12: =IF(خ۷!P87="ناقص","ناقص",خ۷!P86) -> 0 | K12: =IF(تجمیع!P87="ناقص","ناقص",تجمیع!P86) -> 0
A13: 8 | B13: گویه‌های م۷: تغییر ذائقه مصرف‌کننده و محدودیت بازار هدف | C13: 3 | D13: =IF(خ۱!P99="ناقص","ناقص",خ۱!P98) -> 0 | E13: =IF(خ۲!P99="ناقص","ناقص",خ۲!P98) -> 0 | F13: =IF(خ۳!P99="ناقص","ناقص",خ۳!P98) -> 0 | G13: =IF(خ۴!P99="ناقص","ناقص",خ۴!P98) -> 0 | H13: =IF(خ۵!P99="ناقص","ناقص",خ۵!P98) -> 0 | I13: =IF(خ۶!P99="ناقص","ناقص",خ۶!P98) -> 0 | J13: =IF(خ۷!P99="ناقص","ناقص",خ۷!P98) -> 0 | K13: =IF(تجمیع!P99="ناقص","ناقص",تجمیع!P98) -> 0
A14: 9 | B14: گویه‌های م۸: ناپایداری تأمین و نوسان بهای مواد اولیه | C14: 3 | D14: =IF(خ۱!P111="ناقص","ناقص",خ۱!P110) -> 0 | E14: =IF(خ۲!P111="ناقص","ناقص",خ۲!P110) -> 0 | F14: =IF(خ۳!P111="ناقص","ناقص",خ۳!P110) -> 0 | G14: =IF(خ۴!P111="ناقص","ناقص",خ۴!P110) -> 0 | H14: =IF(خ۵!P111="ناقص","ناقص",خ۵!P110) -> 0 | I14: =IF(خ۶!P111="ناقص","ناقص",خ۶!P110) -> 0 | J14: =IF(خ۷!P111="ناقص","ناقص",خ۷!P110) -> 0 | K14: =IF(تجمیع!P111="ناقص","ناقص",تجمیع!P110) -> 0
A15: 10 | B15: گویه‌های م۹: فشارهای اقتصاد کلان و کاهش قدرت خرید | C15: 2 | D15: =IF(خ۱!P123="ناقص","ناقص",خ۱!P122) -> 0 | E15: =IF(خ۲!P123="ناقص","ناقص",خ۲!P122) -> 0 | F15: =IF(خ۳!P123="ناقص","ناقص",خ۳!P122) -> 0 | G15: =IF(خ۴!P123="ناقص","ناقص",خ۴!P122) -> 0 | H15: =IF(خ۵!P123="ناقص","ناقص",خ۵!P122) -> 0 | I15: =IF(خ۶!P123="ناقص","ناقص",خ۶!P122) -> 0 | J15: =IF(خ۷!P123="ناقص","ناقص",خ۷!P122) -> 0 | K15: =IF(تجمیع!P123="ناقص","ناقص",تجمیع!P122) -> 0
B17: مقایسه‌های ثبت‌شده (از ۷۰) | D17: =ورودی!G4 -> 70 | E17: =ورودی!H4 -> 70 | F17: =ورودی!I4 -> 70 | G17: =ورودی!J4 -> 70 | H17: =ورودی!K4 -> 70 | I17: =ورودی!L4 -> 70 | J17: =ورودی!M4 -> 70 | K17: =COUNT(نسبت!N9:N78) -> 70
B18: ماتریس‌های ناسازگار | D18: =COUNTIF(D6:D15,">"&$C$3) -> 0 | E18: =COUNTIF(E6:E15,">"&$C$3) -> 0 | F18: =COUNTIF(F6:F15,">"&$C$3) -> 0 | G18: =COUNTIF(G6:G15,">"&$C$3) -> 0 | H18: =COUNTIF(H6:H15,">"&$C$3) -> 0 | I18: =COUNTIF(I6:I15,">"&$C$3) -> 0 | J18: =COUNTIF(J6:J15,">"&$C$3) -> 0 | K18: =COUNTIF(K6:K15,">"&$C$3) -> 0
B19: ماتریس‌های ناقص | D19: =COUNTIF(D6:D15,"ناقص") -> 0 | E19: =COUNTIF(E6:E15,"ناقص") -> 0 | F19: =COUNTIF(F6:F15,"ناقص") -> 0 | G19: =COUNTIF(G6:G15,"ناقص") -> 0 | H19: =COUNTIF(H6:H15,"ناقص") -> 0 | I19: =COUNTIF(I6:I15,"ناقص") -> 0 | J19: =COUNTIF(J6:J15,"ناقص") -> 0 | K19: =COUNTIF(K6:K15,"ناقص") -> 0
B20: وضعیت | D20: =IF(D17=0,"—",IF(D19>0,"ناقص",IF(D18>0,"بازنگری","تأیید"))) -> تأیید | E20: =IF(E17=0,"—",IF(E19>0,"ناقص",IF(E18>0,"بازنگری","تأیید"))) -> تأیید | F20: =IF(F17=0,"—",IF(F19>0,"ناقص",IF(F18>0,"بازنگری","تأیید"))) -> تأیید | G20: =IF(G17=0,"—",IF(G19>0,"ناقص",IF(G18>0,"بازنگری","تأیید"))) -> تأیید | H20: =IF(H17=0,"—",IF(H19>0,"ناقص",IF(H18>0,"بازنگری","تأیید"))) -> تأیید | I20: =IF(I17=0,"—",IF(I19>0,"ناقص",IF(I18>0,"بازنگری","تأیید"))) -> تأیید | J20: =IF(J17=0,"—",IF(J19>0,"ناقص",IF(J18>0,"بازنگری","تأیید"))) -> تأیید | K20: =IF(K17=0,"—",IF(K19>0,"ناقص",IF(K18>0,"بازنگری","تأیید"))) -> تأیید
A22: «بازنگری»: دست‌کم یک ماتریس این خبره از حد مجاز ناسازگارتر است؛ مقایسهٔ قرمزشده در برگهٔ همان خبره را با او مرور کنید. «تأیید»: همهٔ ماتریس‌های او کامل و سازگارند. «تجمیعی» ماتریس‌های ساخته‌شده از میانگین هندسی خبرگان است.

Sheet نتیجه
A1: نتایج: وزن مؤلفه‌ها و گویه‌ها به روش مقایسهٔ زوجی (AHP) — بر پایهٔ ماتریس‌های برآوردی
A3: ="وضعیت داده‌ها: "&IF(سازگاری!K17=0,"هنوز مقایسه‌ای ثبت نشده است.",IF(COUNTIF(ورودی!G5:M5,"کامل")<7,"نتایج موقت است: فقط "&COUNTIF(ورودی!G5:M5,"کامل")&" خبره از 7 خبره پاسخ کامل داده‌اند.","پاسخ هر 7 خبره کامل است.")) -> وضعیت داده‌ها: پاسخ هر 7 خبره کامل است.
A4: =IF(SUM(سازگاری!D18:J18)>0,"توجه: "&SUM(سازگاری!D18:J18)&" ماتریس از ماتریس‌های خبرگان ناسازگارتر از حد مجاز است؛ برگهٔ «سازگاری» را ببینید.","")
A5: وزن‌ها از ماتریس‌های تجمیعی (میانگین هندسی خبرگان) به دست می‌آیند. وزن کلی گویه = وزن مؤلفه × وزن محلی گویه. «تغییر رتبه» = رتبهٔ مستقیم − رتبهٔ مقایسهٔ زوجی (مثبت: در مقایسهٔ زوجی بالاتر آمده است).
A7: جدول ۱. وزن مؤلفه‌ها
A8: کد | B8: مؤلفه | C8: وزن (مقایسهٔ زوجی) | D8: رتبه | E8: وزن (روش مستقیم) | F8: رتبه (مستقیم) | G8: تغییر رتبه | H8: رتبهٔ میانگین (زوجی) | I8: رتبهٔ میانگین (مستقیم)
A9: م۱ | B9: آسیب‌پذیری ساختاری ناشی از تمرکز بر محصول واحد | C9: =تجمیع!M7 -> 0.1249275 | D9: =IF(ISNUMBER(C9),RANK(C9,$C$9:$C$17),"") -> 4 | E9: =وزن_مستقیم!D39 -> 0.11579286 | F9: =وزن_مستقیم!E39 -> 4 | G9: =IF(ISNUMBER(D9),F9-D9,"") -> 0 | H9: =IF(ISNUMBER(C9),RANK(C9,$C$9:$C$17)+(COUNTIF($C$9:$C$17,C9)-1)/2,"") -> 4 | I9: =RANK(E9,$E$9:$E$17)+(COUNTIF($E$9:$E$17,E9)-1)/2 -> 4
A10: م۲ | B10: ضعف برندسازی و دشواری تمایز محصول | C10: =تجمیع!M8 -> 0.067520412 | D10: =IF(ISNUMBER(C10),RANK(C10,$C$9:$C$17),"") -> 9 | E10: =وزن_مستقیم!D40 -> 0.09649405 | F10: =وزن_مستقیم!E40 -> 9 | G10: =IF(ISNUMBER(D10),F10-D10,"") -> 0 | H10: =IF(ISNUMBER(C10),RANK(C10,$C$9:$C$17)+(COUNTIF($C$9:$C$17,C10)-1)/2,"") -> 9 | I10: =RANK(E10,$E$9:$E$17)+(COUNTIF($E$9:$E$17,E10)-1)/2 -> 9
A11: م۳ | B11: دشواری جذب و حفظ مشتری و وفاداری پایین | C11: =تجمیع!M9 -> 0.083530637 | D11: =IF(ISNUMBER(C11),RANK(C11,$C$9:$C$17),"") -> 7 | E11: =وزن_مستقیم!D41 -> 0.10292699 | F11: =وزن_مستقیم!E41 -> 7 | G11: =IF(ISNUMBER(D11),F11-D11,"") -> 0 | H11: =IF(ISNUMBER(C11),RANK(C11,$C$9:$C$17)+(COUNTIF($C$9:$C$17,C11)-1)/2,"") -> 7 | I11: =RANK(E11,$E$9:$E$17)+(COUNTIF($E$9:$E$17,E11)-1)/2 -> 7
A12: م۴ | B12: ضعف در برنامه‌ریزی، پیش‌بینی و مدیریت فروش | C12: =تجمیع!M10 -> 0.079934227 | D12: =IF(ISNUMBER(C12),RANK(C12,$C$9:$C$17),"") -> 8 | E12: =وزن_مستقیم!D42 -> 0.10228369 | F12: =وزن_مستقیم!E42 -> 8 | G12: =IF(ISNUMBER(D12),F12-D12,"") -> 0 | H12: =IF(ISNUMBER(C12),RANK(C12,$C$9:$C$17)+(COUNTIF($C$9:$C$17,C12)-1)/2,"") -> 8 | I12: =RANK(E12,$E$9:$E$17)+(COUNTIF($E$9:$E$17,E12)-1)/2 -> 8
A13: م۵ | B13: ناکارآمدی و هزینه‌بری شبکه توزیع و فروش | C13: =تجمیع!M11 -> 0.10997707 | D13: =IF(ISNUMBER(C13),RANK(C13,$C$9:$C$17),"") -> 6 | E13: =وزن_مستقیم!D43 -> 0.11096816 | F13: =وزن_مستقیم!E43 -> 6 | G13: =IF(ISNUMBER(D13),F13-D13,"") -> 0 | H13: =IF(ISNUMBER(C13),RANK(C13,$C$9:$C$17)+(COUNTIF($C$9:$C$17,C13)-1)/2,"") -> 6 | I13: =RANK(E13,$E$9:$E$17)+(COUNTIF($E$9:$E$17,E13)-1)/2 -> 6
A14: م۶ | B14: شدت رقابت و فشار قیمتی بازار | C14: =تجمیع!M12 -> 0.12971074 | D14: =IF(ISNUMBER(C14),RANK(C14,$C$9:$C$17),"") -> 3 | E14: =وزن_مستقیم!D44 -> 0.11707945 | F14: =وزن_مستقیم!E44 -> 3 | G14: =IF(ISNUMBER(D14),F14-D14,"") -> 0 | H14: =IF(ISNUMBER(C14),RANK(C14,$C$9:$C$17)+(COUNTIF($C$9:$C$17,C14)-1)/2,"") -> 3 | I14: =RANK(E14,$E$9:$E$17)+(COUNTIF($E$9:$E$17,E14)-1)/2 -> 3
A15: م۷ | B15: تغییر ذائقه مصرف‌کننده و محدودیت بازار هدف | C15: =تجمیع!M13 -> 0.13223952 | D15: =IF(ISNUMBER(C15),RANK(C15,$C$9:$C$17),"") -> 2 | E15: =وزن_مستقیم!D45 -> 0.11965262 | F15: =وزن_مستقیم!E45 -> 2 | G15: =IF(ISNUMBER(D15),F15-D15,"") -> 0 | H15: =IF(ISNUMBER(C15),RANK(C15,$C$9:$C$17)+(COUNTIF($C$9:$C$17,C15)-1)/2,"") -> 2 | I15: =RANK(E15,$E$9:$E$17)+(COUNTIF($E$9:$E$17,E15)-1)/2 -> 2
A16: م۸ | B16: ناپایداری تأمین و نوسان بهای مواد اولیه | C16: =تجمیع!M14 -> 0.11748209 | D16: =IF(ISNUMBER(C16),RANK(C16,$C$9:$C$17),"") -> 5 | E16: =وزن_مستقیم!D46 -> 0.11321968 | F16: =وزن_مستقیم!E46 -> 5 | G16: =IF(ISNUMBER(D16),F16-D16,"") -> 0 | H16: =IF(ISNUMBER(C16),RANK(C16,$C$9:$C$17)+(COUNTIF($C$9:$C$17,C16)-1)/2,"") -> 5 | I16: =RANK(E16,$E$9:$E$17)+(COUNTIF($E$9:$E$17,E16)-1)/2 -> 5
A17: م۹ | B17: فشارهای اقتصاد کلان و کاهش قدرت خرید | C17: =تجمیع!M15 -> 0.15467781 | D17: =IF(ISNUMBER(C17),RANK(C17,$C$9:$C$17),"") -> 1 | E17: =وزن_مستقیم!D47 -> 0.1215825 | F17: =وزن_مستقیم!E47 -> 1 | G17: =IF(ISNUMBER(D17),F17-D17,"") -> 0 | H17: =IF(ISNUMBER(C17),RANK(C17,$C$9:$C$17)+(COUNTIF($C$9:$C$17,C17)-1)/2,"") -> 1 | I17: =RANK(E17,$E$9:$E$17)+(COUNTIF($E$9:$E$17,E17)-1)/2 -> 1
B18: مجموع | C18: =IF(COUNT(C9:C17)=9,SUM(C9:C17),"") -> 1 | E18: =SUM(E9:E17) -> 1
B19: ضریب همبستگی اسپیرمن میان دو رتبه‌بندی (مؤلفه‌ها) | C19: =IFERROR(CORREL(H9:H17,I9:I17),"—") -> 1
A22: جدول ۲. وزن گویه‌ها
A23: کد | B23: گویه | C23: مؤلفه | D23: وزن محلی (درون مؤلفه) | E23: وزن مؤلفه | F23: وزن کلی (مقایسهٔ زوجی) | G23: رتبه | H23: وزن (روش مستقیم) | I23: رتبه (مستقیم) | J23: تغییر رتبه | K23: رتبهٔ میانگین (زوجی) | L23: رتبهٔ میانگین (مستقیم)
A24: گ۱ | B24: وابستگی کامل درآمد و سودآوری شرکت به تقاضای یک محصول | C24: م۱ | D24: =تجمیع!M21 -> 0.36456473 | E24: =C9 -> 0.1249275 | F24: =IF(AND(ISNUMBER(D24),ISNUMBER(E24)),D24*E24,"") -> 0.045544158 | G24: =IF(ISNUMBER(F24),RANK(F24,$F$24:$F$52),"") -> 7 | H24: =وزن_مستقیم!L5 -> 0.037530266 | I24: =وزن_مستقیم!M5 -> 6 | J24: =IF(ISNUMBER(G24),I24-G24,"") -> -1 | K24: =IF(ISNUMBER(F24),RANK(F24,$F$24:$F$52)+(COUNTIF($F$24:$F$52,F24)-1)/2,"") -> 7.5 | L24: =RANK(H24,$H$24:$H$52)+(COUNTIF($H$24:$H$52,H24)-1)/2 -> 7
A25: گ۲ | B25: نبود امکان جبران افت فروش از محل سایر اقلام سبد محصول | C25: م۱ | D25: =تجمیع!M22 -> 0.36456473 | E25: =C9 -> 0.1249275 | F25: =IF(AND(ISNUMBER(D25),ISNUMBER(E25)),D25*E25,"") -> 0.045544158 | G25: =IF(ISNUMBER(F25),RANK(F25,$F$24:$F$52),"") -> 7 | H25: =وزن_مستقیم!L6 -> 0.037530266 | I25: =وزن_مستقیم!M6 -> 6 | J25: =IF(ISNUMBER(G25),I25-G25,"") -> -1 | K25: =IF(ISNUMBER(F25),RANK(F25,$F$24:$F$52)+(COUNTIF($F$24:$F$52,F25)-1)/2,"") -> 7.5 | L25: =RANK(H25,$H$24:$H$52)+(COUNTIF($H$24:$H$52,H25)-1)/2 -> 7
A26: گ۳ | B26: کاهش انعطاف‌پذیری و کندی واکنش شرکت به تغییرات بازار | C26: م۱ | D26: =تجمیع!M23 -> 0.27087055 | E26: =C9 -> 0.1249275 | F26: =IF(AND(ISNUMBER(D26),ISNUMBER(E26)),D26*E26,"") -> 0.033839179 | G26: =IF(ISNUMBER(F26),RANK(F26,$F$24:$F$52),"") -> 10 | H26: =وزن_مستقیم!L7 -> 0.033898305 | I26: =وزن_مستقیم!M7 -> 9 | J26: =IF(ISNUMBER(G26),I26-G26,"") -> -1 | K26: =IF(ISNUMBER(F26),RANK(F26,$F$24:$F$52)+(COUNTIF($F$24:$F$52,F26)-1)/2,"") -> 10 | L26: =RANK(H26,$H$24:$H$52)+(COUNTIF($H$24:$H$52,H26)-1)/2 -> 17
A27: گ۴ | B27: ضعف در برندسازی و تبلیغات و کمرنگ بودن جایگاه برند در ذهن مشتری | C27: م۲ | D27: =تجمیع!M33 -> 0.32215566 | E27: =C10 -> 0.067520412 | F27: =IF(AND(ISNUMBER(D27),ISNUMBER(E27)),D27*E27,"") -> 0.021752083 | G27: =IF(ISNUMBER(F27),RANK(F27,$F$24:$F$52),"") -> 24 | H27: =وزن_مستقیم!L8 -> 0.033898305 | I27: =وزن_مستقیم!M8 -> 9 | J27: =IF(ISNUMBER(G27),I27-G27,"") -> -15 | K27: =IF(ISNUMBER(F27),RANK(F27,$F$24:$F$52)+(COUNTIF($F$24:$F$52,F27)-1)/2,"") -> 24.5 | L27: =RANK(H27,$H$24:$H$52)+(COUNTIF($H$24:$H$52,H27)-1)/2 -> 17
A28: گ۵ | B28: دشواری ایجاد تمایز نسبت به محصولات رقیب | C28: م۲ | D28: =تجمیع!M34 -> 0.32215566 | E28: =C10 -> 0.067520412 | F28: =IF(AND(ISNUMBER(D28),ISNUMBER(E28)),D28*E28,"") -> 0.021752083 | G28: =IF(ISNUMBER(F28),RANK(F28,$F$24:$F$52),"") -> 24 | H28: =وزن_مستقیم!L9 -> 0.033898305 | I28: =وزن_مستقیم!M9 -> 9 | J28: =IF(ISNUMBER(G28),I28-G28,"") -> -15 | K28: =IF(ISNUMBER(F28),RANK(F28,$F$24:$F$52)+(COUNTIF($F$24:$F$52,F28)-1)/2,"") -> 24.5 | L28: =RANK(H28,$H$24:$H$52)+(COUNTIF($H$24:$H$52,H28)-1)/2 -> 17
A29: گ۶ | B29: نبود نوآوری و توسعه محصول | C29: م۲ | D29: =تجمیع!M35 -> 0.17784434 | E29: =C10 -> 0.067520412 | F29: =IF(AND(ISNUMBER(D29),ISNUMBER(E29)),D29*E29,"") -> 0.012008123 | G29: =IF(ISNUMBER(F29),RANK(F29,$F$24:$F$52),"") -> 28 | H29: =وزن_مستقیم!L10 -> 0.026634383 | I29: =وزن_مستقیم!M10 -> 27 | J29: =IF(ISNUMBER(G29),I29-G29,"") -> -1 | K29: =IF(ISNUMBER(F29),RANK(F29,$F$24:$F$52)+(COUNTIF($F$24:$F$52,F29)-1)/2,"") -> 28.5 | L29: =RANK(H29,$H$24:$H$52)+(COUNTIF($H$24:$H$52,H29)-1)/2 -> 28
A30: گ۷ | B30: کم‌توجهی به تحقیقات بازار و مطالعه رفتار مصرف‌کننده | C30: م۲ | D30: =تجمیع!M36 -> 0.17784434 | E30: =C10 -> 0.067520412 | F30: =IF(AND(ISNUMBER(D30),ISNUMBER(E30)),D30*E30,"") -> 0.012008123 | G30: =IF(ISNUMBER(F30),RANK(F30,$F$24:$F$52),"") -> 28 | H30: =وزن_مستقیم!L11 -> 0.026634383 | I30: =وزن_مستقیم!M11 -> 27 | J30: =IF(ISNUMBER(G30),I30-G30,"") -> -1 | K30: =IF(ISNUMBER(F30),RANK(F30,$F$24:$F$52)+(COUNTIF($F$24:$F$52,F30)-1)/2,"") -> 28.5 | L30: =RANK(H30,$H$24:$H$52)+(COUNTIF($H$24:$H$52,H30)-1)/2 -> 28
A31: گ۸ | B31: دشواری جذب مشتری جدید | C31: م۳ | D31: =تجمیع!M45 -> 0.37411847 | E31: =C11 -> 0.083530637 | F31: =IF(AND(ISNUMBER(D31),ISNUMBER(E31)),D31*E31,"") -> 0.031250354 | G31: =IF(ISNUMBER(F31),RANK(F31,$F$24:$F$52),"") -> 16 | H31: =وزن_مستقیم!L12 -> 0.033898305 | I31: =وزن_مستقیم!M12 -> 9 | J31: =IF(ISNUMBER(G31),I31-G31,"") -> -7 | K31: =IF(ISNUMBER(F31),RANK(F31,$F$24:$F$52)+(COUNTIF($F$24:$F$52,F31)-1)/2,"") -> 16.5 | L31: =RANK(H31,$H$24:$H$52)+(COUNTIF($H$24:$H$52,H31)-1)/2 -> 17
A32: گ۹ | B32: وفاداری پایین مشتری به شرکت تک‌محصولی | C32: م۳ | D32: =تجمیع!M46 -> 0.37411847 | E32: =C11 -> 0.083530637 | F32: =IF(AND(ISNUMBER(D32),ISNUMBER(E32)),D32*E32,"") -> 0.031250354 | G32: =IF(ISNUMBER(F32),RANK(F32,$F$24:$F$52),"") -> 16 | H32: =وزن_مستقیم!L13 -> 0.033898305 | I32: =وزن_مستقیم!M13 -> 9 | J32: =IF(ISNUMBER(G32),I32-G32,"") -> -7 | K32: =IF(ISNUMBER(F32),RANK(F32,$F$24:$F$52)+(COUNTIF($F$24:$F$52,F32)-1)/2,"") -> 16.5 | L32: =RANK(H32,$H$24:$H$52)+(COUNTIF($H$24:$H$52,H32)-1)/2 -> 17
A33: گ۱۰ | B33: نبود پیشنهاد تازه برای حفظ و فعال‌سازی مجدد مشتریان فعلی | C33: م۳ | D33: =تجمیع!M47 -> 0.25176306 | E33: =C11 -> 0.083530637 | F33: =IF(AND(ISNUMBER(D33),ISNUMBER(E33)),D33*E33,"") -> 0.021029929 | G33: =IF(ISNUMBER(F33),RANK(F33,$F$24:$F$52),"") -> 26 | H33: =وزن_مستقیم!L14 -> 0.02905569 | I33: =وزن_مستقیم!M14 -> 26 | J33: =IF(ISNUMBER(G33),I33-G33,"") -> 0 | K33: =IF(ISNUMBER(F33),RANK(F33,$F$24:$F$52)+(COUNTIF($F$24:$F$52,F33)-1)/2,"") -> 26 | L33: =RANK(H33,$H$24:$H$52)+(COUNTIF($H$24:$H$52,H33)-1)/2 -> 26
A34: گ۱۱ | B34: ضعف در پیش‌بینی دقیق تقاضای بازار | C34: م۴ | D34: =تجمیع!M57 -> 0.28152798 | E34: =C12 -> 0.079934227 | F34: =IF(AND(ISNUMBER(D34),ISNUMBER(E34)),D34*E34,"") -> 0.022503722 | G34: =IF(ISNUMBER(F34),RANK(F34,$F$24:$F$52),"") -> 21 | H34: =وزن_مستقیم!L15 -> 0.033898305 | I34: =وزن_مستقیم!M15 -> 9 | J34: =IF(ISNUMBER(G34),I34-G34,"") -> -12 | K34: =IF(ISNUMBER(F34),RANK(F34,$F$24:$F$52)+(COUNTIF($F$24:$F$52,F34)-1)/2,"") -> 22 | L34: =RANK(H34,$H$24:$H$52)+(COUNTIF($H$24:$H$52,H34)-1)/2 -> 17
A35: گ۱۲ | B35: ضعف در برنامه‌ریزی و مدیریت موجودی | C35: م۴ | D35: =تجمیع!M58 -> 0.28152798 | E35: =C12 -> 0.079934227 | F35: =IF(AND(ISNUMBER(D35),ISNUMBER(E35)),D35*E35,"") -> 0.022503722 | G35: =IF(ISNUMBER(F35),RANK(F35,$F$24:$F$52),"") -> 21 | H35: =وزن_مستقیم!L16 -> 0.033898305 | I35: =وزن_مستقیم!M16 -> 9 | J35: =IF(ISNUMBER(G35),I35-G35,"") -> -12 | K35: =IF(ISNUMBER(F35),RANK(F35,$F$24:$F$52)+(COUNTIF($F$24:$F$52,F35)-1)/2,"") -> 22 | L35: =RANK(H35,$H$24:$H$52)+(COUNTIF($H$24:$H$52,H35)-1)/2 -> 17
A36: گ۱۳ | B36: ضعف در نظام برنامه‌ریزی و اطلاعات فروش | C36: م۴ | D36: =تجمیع!M59 -> 0.15541605 | E36: =C12 -> 0.079934227 | F36: =IF(AND(ISNUMBER(D36),ISNUMBER(E36)),D36*E36,"") -> 0.012423062 | G36: =IF(ISNUMBER(F36),RANK(F36,$F$24:$F$52),"") -> 27 | H36: =وزن_مستقیم!L17 -> 0.026634383 | I36: =وزن_مستقیم!M17 -> 27 | J36: =IF(ISNUMBER(G36),I36-G36,"") -> 0 | K36: =IF(ISNUMBER(F36),RANK(F36,$F$24:$F$52)+(COUNTIF($F$24:$F$52,F36)-1)/2,"") -> 27 | L36: =RANK(H36,$H$24:$H$52)+(COUNTIF($H$24:$H$52,H36)-1)/2 -> 28
A37: گ۱۴ | B37: محدودیت منابع مالی برای توزیع و ترویج محصول | C37: م۴ | D37: =تجمیع!M60 -> 0.28152798 | E37: =C12 -> 0.079934227 | F37: =IF(AND(ISNUMBER(D37),ISNUMBER(E37)),D37*E37,"") -> 0.022503722 | G37: =IF(ISNUMBER(F37),RANK(F37,$F$24:$F$52),"") -> 21 | H37: =وزن_مستقیم!L18 -> 0.033898305 | I37: =وزن_مستقیم!M18 -> 9 | J37: =IF(ISNUMBER(G37),I37-G37,"") -> -12 | K37: =IF(ISNUMBER(F37),RANK(F37,$F$24:$F$52)+(COUNTIF($F$24:$F$52,F37)-1)/2,"") -> 22 | L37: =RANK(H37,$H$24:$H$52)+(COUNTIF($H$24:$H$52,H37)-1)/2 -> 17
A38: گ۱۵ | B38: هزینه بالای پخش و توزیع به ازای یک قلم کالا | C38: م۵ | D38: =تجمیع!M69 -> 0.30969423 | E38: =C13 -> 0.10997707 | F38: =IF(AND(ISNUMBER(D38),ISNUMBER(E38)),D38*E38,"") -> 0.034059263 | G38: =IF(ISNUMBER(F38),RANK(F38,$F$24:$F$52),"") -> 9 | H38: =وزن_مستقیم!L19 -> 0.037530266 | I38: =وزن_مستقیم!M19 -> 6 | J38: =IF(ISNUMBER(G38),I38-G38,"") -> -3 | K38: =IF(ISNUMBER(F38),RANK(F38,$F$24:$F$52)+(COUNTIF($F$24:$F$52,F38)-1)/2,"") -> 9 | L38: =RANK(H38,$H$24:$H$52)+(COUNTIF($H$24:$H$52,H38)-1)/2 -> 7
A39: گ۱۶ | B39: کوچک بودن شبکه فروش و پوشش محدود بازار | C39: م۵ | D39: =تجمیع!M70 -> 0.23010192 | E39: =C13 -> 0.10997707 | F39: =IF(AND(ISNUMBER(D39),ISNUMBER(E39)),D39*E39,"") -> 0.025305935 | G39: =IF(ISNUMBER(F39),RANK(F39,$F$24:$F$52),"") -> 18 | H39: =وزن_مستقیم!L20 -> 0.033898305 | I39: =وزن_مستقیم!M20 -> 9 | J39: =IF(ISNUMBER(G39),I39-G39,"") -> -9 | K39: =IF(ISNUMBER(F39),RANK(F39,$F$24:$F$52)+(COUNTIF($F$24:$F$52,F39)-1)/2,"") -> 19 | L39: =RANK(H39,$H$24:$H$52)+(COUNTIF($H$24:$H$52,H39)-1)/2 -> 17
A40: گ۱۷ | B40: کاهش قدرت چانه‌زنی در برابر شبکه توزیع و خرده‌فروشی چندمحصولی | C40: م۵ | D40: =تجمیع!M71 -> 0.23010192 | E40: =C13 -> 0.10997707 | F40: =IF(AND(ISNUMBER(D40),ISNUMBER(E40)),D40*E40,"") -> 0.025305935 | G40: =IF(ISNUMBER(F40),RANK(F40,$F$24:$F$52),"") -> 18 | H40: =وزن_مستقیم!L21 -> 0.033898305 | I40: =وزن_مستقیم!M21 -> 9 | J40: =IF(ISNUMBER(G40),I40-G40,"") -> -9 | K40: =IF(ISNUMBER(F40),RANK(F40,$F$24:$F$52)+(COUNTIF($F$24:$F$52,F40)-1)/2,"") -> 19 | L40: =RANK(H40,$H$24:$H$52)+(COUNTIF($H$24:$H$52,H40)-1)/2 -> 17
A41: گ۱۸ | B41: وابستگی به تعداد محدودی مشتری یا کانال فروش | C41: م۵ | D41: =تجمیع!M72 -> 0.23010192 | E41: =C13 -> 0.10997707 | F41: =IF(AND(ISNUMBER(D41),ISNUMBER(E41)),D41*E41,"") -> 0.025305935 | G41: =IF(ISNUMBER(F41),RANK(F41,$F$24:$F$52),"") -> 18 | H41: =وزن_مستقیم!L22 -> 0.033898305 | I41: =وزن_مستقیم!M22 -> 9 | J41: =IF(ISNUMBER(G41),I41-G41,"") -> -9 | K41: =IF(ISNUMBER(F41),RANK(F41,$F$24:$F$52)+(COUNTIF($F$24:$F$52,F41)-1)/2,"") -> 19 | L41: =RANK(H41,$H$24:$H$52)+(COUNTIF($H$24:$H$52,H41)-1)/2 -> 17
A42: گ۱۹ | B42: ورود رقبای جدید و افزایش شدت رقابت | C42: م۶ | D42: =تجمیع!M81 -> 0.5 | E42: =C14 -> 0.12971074 | F42: =IF(AND(ISNUMBER(D42),ISNUMBER(E42)),D42*E42,"") -> 0.064855372 | G42: =IF(ISNUMBER(F42),RANK(F42,$F$24:$F$52),"") -> 2 | H42: =وزن_مستقیم!L23 -> 0.042372881 | I42: =وزن_مستقیم!M23 -> 1 | J42: =IF(ISNUMBER(G42),I42-G42,"") -> -1 | K42: =IF(ISNUMBER(F42),RANK(F42,$F$24:$F$52)+(COUNTIF($F$24:$F$52,F42)-1)/2,"") -> 2 | L42: =RANK(H42,$H$24:$H$52)+(COUNTIF($H$24:$H$52,H42)-1)/2 -> 1.5
A43: گ۲۰ | B43: حضور محصولات جایگزین و برندهای رقیب دارای سبد متنوع | C43: م۶ | D43: =تجمیع!M82 -> 0.25 | E43: =C14 -> 0.12971074 | F43: =IF(AND(ISNUMBER(D43),ISNUMBER(E43)),D43*E43,"") -> 0.032427686 | G43: =IF(ISNUMBER(F43),RANK(F43,$F$24:$F$52),"") -> 13 | H43: =وزن_مستقیم!L24 -> 0.033898305 | I43: =وزن_مستقیم!M24 -> 9 | J43: =IF(ISNUMBER(G43),I43-G43,"") -> -4 | K43: =IF(ISNUMBER(F43),RANK(F43,$F$24:$F$52)+(COUNTIF($F$24:$F$52,F43)-1)/2,"") -> 13.5 | L43: =RANK(H43,$H$24:$H$52)+(COUNTIF($H$24:$H$52,H43)-1)/2 -> 17
A44: گ۲۱ | B44: رقابت قیمتی و نوسان قیمت رقبا | C44: م۶ | D44: =تجمیع!M83 -> 0.25 | E44: =C14 -> 0.12971074 | F44: =IF(AND(ISNUMBER(D44),ISNUMBER(E44)),D44*E44,"") -> 0.032427686 | G44: =IF(ISNUMBER(F44),RANK(F44,$F$24:$F$52),"") -> 13 | H44: =وزن_مستقیم!L25 -> 0.033898305 | I44: =وزن_مستقیم!M25 -> 9 | J44: =IF(ISNUMBER(G44),I44-G44,"") -> -4 | K44: =IF(ISNUMBER(F44),RANK(F44,$F$24:$F$52)+(COUNTIF($F$24:$F$52,F44)-1)/2,"") -> 13.5 | L44: =RANK(H44,$H$24:$H$52)+(COUNTIF($H$24:$H$52,H44)-1)/2 -> 17
...

Sheet نسبت
A1: نسبت‌ها: تبدیل کدهای ورودی به نسبت اهمیت a(ij) و میانگین هندسی خبرگان
A2: هر خانه نسبت اهمیت مورد «الف» به مورد «ب» است: k ← k، 1 ← 1، -k ← 1/k. ستون «میانگین هندسی» داوری ترکیبی خبرگان است (فقط خبرگانی که آن مقایسه را پاسخ داده‌اند). این برگه محاسباتی است.
A8: ردیف | B8: بخش | C8: کد الف | D8: مورد الف | E8: کد ب | F8: مورد ب | G8: خ۱ | H8: خ۲ | I8: خ۳ | J8: خ۴ | K8: خ۵ | L8: خ۶ | M8: خ۷ | N8: میانگین هندسی خبرگان | O8: تعداد خبره
A9: =ورودی!A9 -> 1 | B9: =ورودی!B9 -> الف | C9: =ورودی!C9 -> م۱ | D9: =ورودی!D9 -> آسیب‌پذیری ساختاری ناشی از تمرکز بر محصول واحد | E9: =ورودی!E9 -> م۲ | F9: =ورودی!F9 -> ضعف برندسازی و دشواری تمایز محصول | G9: =IF(ISNUMBER(ورودی!G9),IF(ورودی!G9>0,ورودی!G9,1/ABS(ورودی!G9)),"") -> 2 | H9: =IF(ISNUMBER(ورودی!H9),IF(ورودی!H9>0,ورودی!H9,1/ABS(ورودی!H9)),"") -> 2 | I9: =IF(ISNUMBER(ورودی!I9),IF(ورودی!I9>0,ورودی!I9,1/ABS(ورودی!I9)),"") -> 3 | J9: =IF(ISNUMBER(ورودی!J9),IF(ورودی!J9>0,ورودی!J9,1/ABS(ورودی!J9)),"") -> 2 | K9: =IF(ISNUMBER(ورودی!K9),IF(ورودی!K9>0,ورودی!K9,1/ABS(ورودی!K9)),"") -> 1 | L9: =IF(ISNUMBER(ورودی!L9),IF(ورودی!L9>0,ورودی!L9,1/ABS(ورودی!L9)),"") -> 2 | M9: =IF(ISNUMBER(ورودی!M9),IF(ورودی!M9>0,ورودی!M9,1/ABS(ورودی!M9)),"") -> 2 | N9: =IFERROR(GEOMEAN(G9:M9),"") -> 1.9194712 | O9: =COUNT(G9:M9) -> 7
A10: =ورودی!A10 -> 2 | B10: =ورودی!B10 -> الف | C10: =ورودی!C10 -> م۱ | D10: =ورودی!D10 -> آسیب‌پذیری ساختاری ناشی از تمرکز بر محصول واحد | E10: =ورودی!E10 -> م۳ | F10: =ورودی!F10 -> دشواری جذب و حفظ مشتری و وفاداری پایین | G10: =IF(ISNUMBER(ورودی!G10),IF(ورودی!G10>0,ورودی!G10,1/ABS(ورودی!G10)),"") -> 2 | H10: =IF(ISNUMBER(ورودی!H10),IF(ورودی!H10>0,ورودی!H10,1/ABS(ورودی!H10)),"") -> 2 | I10: =IF(ISNUMBER(ورودی!I10),IF(ورودی!I10>0,ورودی!I10,1/ABS(ورودی!I10)),"") -> 2 | J10: =IF(ISNUMBER(ورودی!J10),IF(ورودی!J10>0,ورودی!J10,1/ABS(ورودی!J10)),"") -> 2 | K10: =IF(ISNUMBER(ورودی!K10),IF(ورودی!K10>0,ورودی!K10,1/ABS(ورودی!K10)),"") -> 1 | L10: =IF(ISNUMBER(ورودی!L10),IF(ورودی!L10>0,ورودی!L10,1/ABS(ورودی!L10)),"") -> 1 | M10: =IF(ISNUMBER(ورودی!M10),IF(ورودی!M10>0,ورودی!M10,1/ABS(ورودی!M10)),"") -> 1 | N10: =IFERROR(GEOMEAN(G10:M10),"") -> 1.4859943 | O10: =COUNT(G10:M10) -> 7
A11: =ورودی!A11 -> 3 | B11: =ورودی!B11 -> الف | C11: =ورودی!C11 -> م۱ | D11: =ورودی!D11 -> آسیب‌پذیری ساختاری ناشی از تمرکز بر محصول واحد | E11: =ورودی!E11 -> م۴ | F11: =ورودی!F11 -> ضعف در برنامه‌ریزی، پیش‌بینی و مدیریت فروش | G11: =IF(ISNUMBER(ورودی!G11),IF(ورودی!G11>0,ورودی!G11,1/ABS(ورودی!G11)),"") -> 2 | H11: =IF(ISNUMBER(ورودی!H11),IF(ورودی!H11>0,ورودی!H11,1/ABS(ورودی!H11)),"") -> 2 | I11: =IF(ISNUMBER(ورودی!I11),IF(ورودی!I11>0,ورودی!I11,1/ABS(ورودی!I11)),"") -> 2 | J11: =IF(ISNUMBER(ورودی!J11),IF(ورودی!J11>0,ورودی!J11,1/ABS(ورودی!J11)),"") -> 2 | K11: =IF(ISNUMBER(ورودی!K11),IF(ورودی!K11>0,ورودی!K11,1/ABS(ورودی!K11)),"") -> 1 | L11: =IF(ISNUMBER(ورودی!L11),IF(ورودی!L11>0,ورودی!L11,1/ABS(ورودی!L11)),"") -> 1 | M11: =IF(ISNUMBER(ورودی!M11),IF(ورودی!M11>0,ورودی!M11,1/ABS(ورودی!M11)),"") -> 1 | N11: =IFERROR(GEOMEAN(G11:M11),"") -> 1.4859943 | O11: =COUNT(G11:M11) -> 7
A12: =ورودی!A12 -> 4 | B12: =ورودی!B12 -> الف | C12: =ورودی!C12 -> م۱ | D12: =ورودی!D12 -> آسیب‌پذیری ساختاری ناشی از تمرکز بر محصول واحد | E12: =ورودی!E12 -> م۵ | F12: =ورودی!F12 -> ناکارآمدی و هزینه‌بری شبکه توزیع و فروش | G12: =IF(ISNUMBER(ورودی!G12),IF(ورودی!G12>0,ورودی!G12,1/ABS(ورودی!G12)),"") -> 1 | H12: =IF(ISNUMBER(ورودی!H12),IF(ورودی!H12>0,ورودی!H12,1/ABS(ورودی!H12)),"") -> 2 | I12: =IF(ISNUMBER(ورودی!I12),IF(ورودی!I12>0,ورودی!I12,1/ABS(ورودی!I12)),"") -> 1 | J12: =IF(ISNUMBER(ورودی!J12),IF(ورودی!J12>0,ورودی!J12,1/ABS(ورودی!J12)),"") -> 1 | K12: =IF(ISNUMBER(ورودی!K12),IF(ورودی!K12>0,ورودی!K12,1/ABS(ورودی!K12)),"") -> 1 | L12: =IF(ISNUMBER(ورودی!L12),IF(ورودی!L12>0,ورودی!L12,1/ABS(ورودی!L12)),"") -> 1 | M12: =IF(ISNUMBER(ورودی!M12),IF(ورودی!M12>0,ورودی!M12,1/ABS(ورودی!M12)),"") -> 1 | N12: =IFERROR(GEOMEAN(G12:M12),"") -> 1.1040895 | O12: =COUNT(G12:M12) -> 7
A13: =ورودی!A13 -> 5 | B13: =ورودی!B13 -> الف | C13: =ورودی!C13 -> م۱ | D13: =ورودی!D13 -> آسیب‌پذیری ساختاری ناشی از تمرکز بر محصول واحد | E13: =ورودی!E13 -> م۶ | F13: =ورودی!F13 -> شدت رقابت و فشار قیمتی بازار | G13: =IF(ISNUMBER(ورودی!G13),IF(ورودی!G13>0,ورودی!G13,1/ABS(ورودی!G13)),"") -> 1 | H13: =IF(ISNUMBER(ورودی!H13),IF(ورودی!H13>0,ورودی!H13,1/ABS(ورودی!H13)),"") -> 1 | I13: =IF(ISNUMBER(ورودی!I13),IF(ورودی!I13>0,ورودی!I13,1/ABS(ورودی!I13)),"") -> 1 | J13: =IF(ISNUMBER(ورودی!J13),IF(ورودی!J13>0,ورودی!J13,1/ABS(ورودی!J13)),"") -> 1 | K13: =IF(ISNUMBER(ورودی!K13),IF(ورودی!K13>0,ورودی!K13,1/ABS(ورودی!K13)),"") -> 1 | L13: =IF(ISNUMBER(ورودی!L13),IF(ورودی!L13>0,ورودی!L13,1/ABS(ورودی!L13)),"") -> 1 | M13: =IF(ISNUMBER(ورودی!M13),IF(ورودی!M13>0,ورودی!M13,1/ABS(ورودی!M13)),"") -> 1 | N13: =IFERROR(GEOMEAN(G13:M13),"") -> 1 | O13: =COUNT(G13:M13) -> 7
A14: =ورودی!A14 -> 6 | B14: =ورودی!B14 -> الف | C14: =ورودی!C14 -> م۱ | D14: =ورودی!D14 -> آسیب‌پذیری ساختاری ناشی از تمرکز بر محصول واحد | E14: =ورودی!E14 -> م۷ | F14: =ورودی!F14 -> تغییر ذائقه مصرف‌کننده و محدودیت بازار هدف | G14: =IF(ISNUMBER(ورودی!G14),IF(ورودی!G14>0,ورودی!G14,1/ABS(ورودی!G14)),"") -> 1 | H14: =IF(ISNUMBER(ورودی!H14),IF(ورودی!H14>0,ورودی!H14,1/ABS(ورودی!H14)),"") -> 1 | I14: =IF(ISNUMBER(ورودی!I14),IF(ورودی!I14>0,ورودی!I14,1/ABS(ورودی!I14)),"") -> 1 | J14: =IF(ISNUMBER(ورودی!J14),IF(ورودی!J14>0,ورودی!J14,1/ABS(ورودی!J14)),"") -> 1 | K14: =IF(ISNUMBER(ورودی!K14),IF(ورودی!K14>0,ورودی!K14,1/ABS(ورودی!K14)),"") -> 1 | L14: =IF(ISNUMBER(ورودی!L14),IF(ورودی!L14>0,ورودی!L14,1/ABS(ورودی!L14)),"") -> 1 | M14: =IF(ISNUMBER(ورودی!M14),IF(ورودی!M14>0,ورودی!M14,1/ABS(ورودی!M14)),"") -> 1 | N14: =IFERROR(GEOMEAN(G14:M14),"") -> 1 | O14: =COUNT(G14:M14) -> 7
A15: =ورودی!A15 -> 7 | B15: =ورودی!B15 -> الف | C15: =ورودی!C15 -> م۱ | D15: =ورودی!D15 -> آسیب‌پذیری ساختاری ناشی از تمرکز بر محصول واحد | E15: =ورودی!E15 -> م۸ | F15: =ورودی!F15 -> ناپایداری تأمین و نوسان بهای مواد اولیه | G15: =IF(ISNUMBER(ورودی!G15),IF(ورودی!G15>0,ورودی!G15,1/ABS(ورودی!G15)),"") -> 1 | H15: =IF(ISNUMBER(ورودی!H15),IF(ورودی!H15>0,ورودی!H15,1/ABS(ورودی!H15)),"") -> 1 | I15: =IF(ISNUMBER(ورودی!I15),IF(ورودی!I15>0,ورودی!I15,1/ABS(ورودی!I15)),"") -> 2 | J15: =IF(ISNUMBER(ورودی!J15),IF(ورودی!J15>0,ورودی!J15,1/ABS(ورودی!J15)),"") -> 1 | K15: =IF(ISNUMBER(ورودی!K15),IF(ورودی!K15>0,ورودی!K15,1/ABS(ورودی!K15)),"") -> 1 | L15: =IF(ISNUMBER(ورودی!L15),IF(ورودی!L15>0,ورودی!L15,1/ABS(ورودی!L15)),"") -> 1 | M15: =IF(ISNUMBER(ورودی!M15),IF(ورودی!M15>0,ورودی!M15,1/ABS(ورودی!M15)),"") -> 1 | N15: =IFERROR(GEOMEAN(G15:M15),"") -> 1.1040895 | O15: =COUNT(G15:M15) -> 7
A16: =ورودی!A16 -> 8 | B16: =ورودی!B16 -> الف | C16: =ورودی!C16 -> م۱ | D16: =ورودی!D16 -> آسیب‌پذیری ساختاری ناشی از تمرکز بر محصول واحد | E16: =ورودی!E16 -> م۹ | F16: =ورودی!F16 -> فشارهای اقتصاد کلان و کاهش قدرت خرید | G16: =IF(ISNUMBER(ورودی!G16),IF(ورودی!G16>0,ورودی!G16,1/ABS(ورودی!G16)),"") -> 1 | H16: =IF(ISNUMBER(ورودی!H16),IF(ورودی!H16>0,ورودی!H16,1/ABS(ورودی!H16)),"") -> 1 | I16: =IF(ISNUMBER(ورودی!I16),IF(ورودی!I16>0,ورودی!I16,1/ABS(ورودی!I16)),"") -> 1 | J16: =IF(ISNUMBER(ورودی!J16),IF(ورودی!J16>0,ورودی!J16,1/ABS(ورودی!J16)),"") -> 1 | K16: =IF(ISNUMBER(ورودی!K16),IF(ورودی!K16>0,ورودی!K16,1/ABS(ورودی!K16)),"") -> 0.5 | L16: =IF(ISNUMBER(ورودی!L16),IF(ورودی!L16>0,ورودی!L16,1/ABS(ورودی!L16)),"") -> 0.5 | M16: =IF(ISNUMBER(ورودی!M16),IF(ورودی!M16>0,ورودی!M16,1/ABS(ورودی!M16)),"") -> 0.5 | N16: =IFERROR(GEOMEAN(G16:M16),"") -> 0.74299714 | O16: =COUNT(G16:M16) -> 7
A17: =ورودی!A17 -> 9 | B17: =ورودی!B17 -> الف | C17: =ورودی!C17 -> م۲ | D17: =ورودی!D17 -> ضعف برندسازی و دشواری تمایز محصول | E17: =ورودی!E17 -> م۳ | F17: =ورودی!F17 -> دشواری جذب و حفظ مشتری و وفاداری پایین | G17: =IF(ISNUMBER(ورودی!G17),IF(ورودی!G17>0,ورودی!G17,1/ABS(ورودی!G17)),"") -> 1 | H17: =IF(ISNUMBER(ورودی!H17),IF(ورودی!H17>0,ورودی!H17,1/ABS(ورودی!H17)),"") -> 1 | I17: =IF(ISNUMBER(ورودی!I17),IF(ورودی!I17>0,ورودی!I17,1/ABS(ورودی!I17)),"") -> 0.5 | J17: =IF(ISNUMBER(ورودی!J17),IF(ورودی!J17>0,ورودی!J17,1/ABS(ورودی!J17)),"") -> 1 | K17: =IF(ISNUMBER(ورودی!K17),IF(ورودی!K17>0,ورودی!K17,1/ABS(ورودی!K17)),"") -> 1 | L17: =IF(ISNUMBER(ورودی!L17),IF(ورودی!L17>0,ورودی!L17,1/ABS(ورودی!L17)),"") -> 1 | M17: =IF(ISNUMBER(ورودی!M17),IF(ورودی!M17>0,ورودی!M17,1/ABS(ورودی!M17)),"") -> 1 | N17: =IFERROR(GEOMEAN(G17:M17),"") -> 0.90572366 | O17: =COUNT(G17:M17) -> 7
A18: =ورودی!A18 -> 10 | B18: =ورودی!B18 -> الف | C18: =ورودی!C18 -> م۲ | D18: =ورودی!D18 -> ضعف برندسازی و دشواری تمایز محصول | E18: =ورودی!E18 -> م۴ | F18: =ورودی!F18 -> ضعف در برنامه‌ریزی، پیش‌بینی و مدیریت فروش | G18: =IF(ISNUMBER(ورودی!G18),IF(ورودی!G18>0,ورودی!G18,1/ABS(ورودی!G18)),"") -> 1 | H18: =IF(ISNUMBER(ورودی!H18),IF(ورودی!H18>0,ورودی!H18,1/ABS(ورودی!H18)),"") -> 1 | I18: =IF(ISNUMBER(ورودی!I18),IF(ورودی!I18>0,ورودی!I18,1/ABS(ورودی!I18)),"") -> 1 | J18: =IF(ISNUMBER(ورودی!J18),IF(ورودی!J18>0,ورودی!J18,1/ABS(ورودی!J18)),"") -> 1 | K18: =IF(ISNUMBER(ورودی!K18),IF(ورودی!K18>0,ورودی!K18,1/ABS(ورودی!K18)),"") -> 1 | L18: =IF(ISNUMBER(ورودی!L18),IF(ورودی!L18>0,ورودی!L18,1/ABS(ورودی!L18)),"") -> 0.5 | M18: =IF(ISNUMBER(ورودی!M18),IF(ورودی!M18>0,ورودی!M18,1/ABS(ورودی!M18)),"") -> 1 | N18: =IFERROR(GEOMEAN(G18:M18),"") -> 0.90572366 | O18: =COUNT(G18:M18) -> 7
A19: =ورودی!A19 -> 11 | B19: =ورودی!B19 -> الف | C19: =ورودی!C19 -> م۲ | D19: =ورودی!D19 -> ضعف برندسازی و دشواری تمایز محصول | E19: =ورودی!E19 -> م۵ | F19: =ورودی!F19 -> ناکارآمدی و هزینه‌بری شبکه توزیع و فروش | G19: =IF(ISNUMBER(ورودی!G19),IF(ورودی!G19>0,ورودی!G19,1/ABS(ورودی!G19)),"") -> 0.5 | H19: =IF(ISNUMBER(ورودی!H19),IF(ورودی!H19>0,ورودی!H19,1/ABS(ورودی!H19)),"") -> 1 | I19: =IF(ISNUMBER(ورودی!I19),IF(ورودی!I19>0,ورودی!I19,1/ABS(ورودی!I19)),"") -> 0.5 | J19: =IF(ISNUMBER(ورودی!J19),IF(ورودی!J19>0,ورودی!J19,1/ABS(ورودی!J19)),"") -> 0.5 | K19: =IF(ISNUMBER(ورودی!K19),IF(ورودی!K19>0,ورودی!K19,1/ABS(ورودی!K19)),"") -> 0.5 | L19: =IF(ISNUMBER(ورودی!L19),IF(ورودی!L19>0,ورودی!L19,1/ABS(ورودی!L19)),"") -> 0.5 | M19: =IF(ISNUMBER(ورودی!M19),IF(ورودی!M19>0,ورودی!M19,1/ABS(ورودی!M19)),"") -> 0.5 | N19: =IFERROR(GEOMEAN(G19:M19),"") -> 0.55204476 | O19: =COUNT(G19:M19) -> 7
A20: =ورودی!A20 -> 12 | B20: =ورودی!B20 -> الف | C20: =ورودی!C20 -> م۲ | D20: =ورودی!D20 -> ضعف برندسازی و دشواری تمایز محصول | E20: =ورودی!E20 -> م۶ | F20: =ورودی!F20 -> شدت رقابت و فشار قیمتی بازار | G20: =IF(ISNUMBER(ورودی!G20),IF(ورودی!G20>0,ورودی!G20,1/ABS(ورودی!G20)),"") -> 0.5 | H20: =IF(ISNUMBER(ورودی!H20),IF(ورودی!H20>0,ورودی!H20,1/ABS(ورودی!H20)),"") -> 0.5 | I20: =IF(ISNUMBER(ورودی!I20),IF(ورودی!I20>0,ورودی!I20,1/ABS(ورودی!I20)),"") -> 0.5 | J20: =IF(ISNUMBER(ورودی!J20),IF(ورودی!J20>0,ورودی!J20,1/ABS(ورودی!J20)),"") -> 0.5 | K20: =IF(ISNUMBER(ورودی!K20),IF(ورودی!K20>0,ورودی!K20,1/ABS(ورودی!K20)),"") -> 0.5 | L20: =IF(ISNUMBER(ورودی!L20),IF(ورودی!L20>0,ورودی!L20,1/ABS(ورودی!L20)),"") -> 0.5 | M20: =IF(ISNUMBER(ورودی!M20),IF(ورودی!M20>0,ورودی!M20,1/ABS(ورودی!M20)),"") -> 0.5 | N20: =IFERROR(GEOMEAN(G20:M20),"") -> 0.5 | O20: =COUNT(G20:M20) -> 7
... A78: =ورودی!A78 -> 70 | B78: =ورودی!B78 -> ب | C78: =ورودی!C78 -> گ۲۸ | D78: =ورودی!D78 -> افزایش بهای تمام‌شده و فشار بر حاشیه سود | E78: =ورودی!E78 -> گ۲۹ | F78: =ورودی!F78 -> کاهش قدرت خرید و مشکلات اقتصادی مصرف‌کننده | G78: =IF(ISNUMBER(ورودی!G78),IF(ورودی!G78>0,ورودی!G78,1/ABS(ورودی!G78)),"") -> 2 | H78: =IF(ISNUMBER(ورودی!H78),IF(ورودی!H78>0,ورودی!H78,1/ABS(ورودی!H78)),"") -> 2 | I78: =IF(ISNUMBER(ورودی!I78),IF(ورودی!I78>0,ورودی!I78,1/ABS(ورودی!I78)),"") -> 2 | J78: =IF(ISNUMBER(ورودی!J78),IF(ورودی!J78>0,ورودی!J78,1/ABS(ورودی!J78)),"") -> 2 | K78: =IF(ISNUMBER(ورودی!K78),IF(ورودی!K78>0,ورودی!K78,1/ABS(ورودی!K78)),"") -> 2 | L78: =IF(ISNUMBER(ورودی!L78),IF(ورودی!L78>0,ورودی!L78,1/ABS(ورودی!L78)),"") -> 2 | M78: =IF(ISNUMBER(ورودی!M78),IF(ورودی!M78>0,ورودی!M78,1/ABS(ورودی!M78)),"") -> 2 | N78: =IFERROR(GEOMEAN(G78:M78),"") -> 2 | O78: =COUNT(G78:M78) -> 7

Sheet تجمیع
A1: ماتریس‌های تجمیعی — میانگین هندسی داوری‌های خبرگان
A2: منبع: برگهٔ «نسبت»، ستون «میانگین هندسی خبرگان». این برگه محاسباتی است و نباید ویرایش شود.
A3: خبرگان با پاسخ کامل: | B3: =COUNTIF(ورودی!G5:M5,"کامل") -> 7 | O3: حد مجاز CR | P3: =راهنما!$C$26 -> 0.1
A5: ماتریس مقایسهٔ مؤلفه‌ها (۹×۹) | Q5: انحراف هر مقایسه از وزن‌های برآوردشده (۱ = کاملاً سازگار)
A6: کد | B6: مورد | C6: م۱ | D6: م۲ | E6: م۳ | F6: م۴ | G6: م۵ | H6: م۶ | I6: م۷ | J6: م۸ | K6: م۹ | L6: میانگین هندسی سطر | M6: وزن | Q6: کد | R6: م۱ | S6: م۲ | T6: م۳ | U6: م۴ | V6: م۵ | W6: م۶ | X6: م۷ | Y6: م۸ | Z6: م۹ | AA6: بیشینهٔ سطر
A7: م۱ | B7: آسیب‌پذیری ساختاری ناشی از تمرکز بر محصول واحد | C7: 1 | D7: =نسبت!N9 -> 1.9194712 | E7: =نسبت!N10 -> 1.4859943 | F7: =نسبت!N11 -> 1.4859943 | G7: =نسبت!N12 -> 1.1040895 | H7: =نسبت!N13 -> 1 | I7: =نسبت!N14 -> 1 | J7: =نسبت!N15 -> 1.1040895 | K7: =نسبت!N16 -> 0.74299714 | L7: =IF($P$8=$P$7*($P$7-1)/2,GEOMEAN(C7:K7),"") -> 1.1612144 | M7: =IF($P$8=$P$7*($P$7-1)/2,L7/SUM($L$7:$L$15),"") -> 0.1249275 | O7: تعداد گزینه‌ها (n) | P7: =ROWS(A7:A15) -> 9 | Q7: م۱ | S7: =IF(AND(ISNUMBER(D7),ISNUMBER($M7),ISNUMBER($M8)),MAX(D7*$M8/$M7,$M7/(D7*$M8)),"") -> 1.0374296 | T7: =IF(AND(ISNUMBER(E7),ISNUMBER($M7),ISNUMBER($M9)),MAX(E7*$M9/$M7,$M7/(E7*$M9)),"") -> 1.0064567 | U7: =IF(AND(ISNUMBER(F7),ISNUMBER($M7),ISNUMBER($M10)),MAX(F7*$M10/$M7,$M7/(F7*$M10)),"") -> 1.0517393 | V7: =IF(AND(ISNUMBER(G7),ISNUMBER($M7),ISNUMBER($M11)),MAX(G7*$M11/$M7,$M7/(G7*$M11)),"") -> 1.0288489 | W7: =IF(AND(ISNUMBER(H7),ISNUMBER($M7),ISNUMBER($M12)),MAX(H7*$M12/$M7,$M7/(H7*$M12)),"") -> 1.0382882 | X7: =IF(AND(ISNUMBER(I7),ISNUMBER($M7),ISNUMBER($M13)),MAX(I7*$M13/$M7,$M7/(I7*$M13)),"") -> 1.0585301 | Y7: =IF(AND(ISNUMBER(J7),ISNUMBER($M7),ISNUMBER($M14)),MAX(J7*$M14/$M7,$M7/(J7*$M14)),"") -> 1.0382882 | Z7: =IF(AND(ISNUMBER(K7),ISNUMBER($M7),ISNUMBER($M15)),MAX(K7*$M15/$M7,$M7/(K7*$M15)),"") -> 1.0870334 | AA7: =IF(COUNT(R7:Z7)=0,"",MAX(R7:Z7)) -> 1.0870334
A8: م۲ | B8: ضعف برندسازی و دشواری تمایز محصول | C8: =IF(ISNUMBER(D7),1/D7,"") -> 0.52097681 | D8: 1 | E8: =نسبت!N17 -> 0.90572366 | F8: =نسبت!N18 -> 0.90572366 | G8: =نسبت!N19 -> 0.55204476 | H8: =نسبت!N20 -> 0.5 | I8: =نسبت!N21 -> 0.46398785 | J8: =نسبت!N22 -> 0.55204476 | K8: =نسبت!N23 -> 0.5 | L8: =IF($P$8=$P$7*($P$7-1)/2,GEOMEAN(C8:K8),"") -> 0.62760941 | M8: =IF($P$8=$P$7*($P$7-1)/2,L8/SUM($L$7:$L$15),"") -> 0.067520412 | O8: مقایسه‌های ثبت‌شده | P8: =(COUNT(C7:K15)-$P$7)/2 -> 36 | Q8: م۲ | T8: =IF(AND(ISNUMBER(E8),ISNUMBER($M8),ISNUMBER($M9)),MAX(E8*$M9/$M8,$M8/(E8*$M9)),"") -> 1.120486 | U8: =IF(AND(ISNUMBER(F8),ISNUMBER($M8),ISNUMBER($M10)),MAX(F8*$M10/$M8,$M8/(F8*$M10)),"") -> 1.0722435 | V8: =IF(AND(ISNUMBER(G8),ISNUMBER($M8),ISNUMBER($M11)),MAX(G8*$M11/$M8,$M8/(G8*$M11)),"") -> 1.1121379 | W8: =IF(AND(ISNUMBER(H8),ISNUMBER($M8),ISNUMBER($M12)),MAX(H8*$M12/$M8,$M8/(H8*$M12)),"") -> 1.041092 | X8: =IF(AND(ISNUMBER(I8),ISNUMBER($M8),ISNUMBER($M13)),MAX(I8*$M13/$M8,$M8/(I8*$M13)),"") -> 1.1004422 | Y8: =IF(AND(ISNUMBER(J8),ISNUMBER($M8),ISNUMBER($M14)),MAX(J8*$M14/$M8,$M8/(J8*$M14)),"") -> 1.041092 | Z8: =IF(AND(ISNUMBER(K8),ISNUMBER($M8),ISNUMBER($M15)),MAX(K8*$M15/$M8,$M8/(K8*$M15)),"") -> 1.1454152 | AA8: =IF(COUNT(R8:Z8)=0,"",MAX(R8:Z8)) -> 1.1454152
A9: م۳ | B9: دشواری جذب و حفظ مشتری و وفاداری پایین | C9: =IF(ISNUMBER(E7),1/E7,"") -> 0.6729501 | D9: =IF(ISNUMBER(E8),1/E8,"") -> 1.1040895 | E9: 1 | F9: =نسبت!N24 -> 1 | G9: =نسبت!N25 -> 0.90572366 | H9: =نسبت!N26 -> 0.6729501 | I9: =نسبت!N27 -> 0.60950683 | J9: =نسبت!N28 -> 0.74299714 | K9: =نسبت!N29 -> 0.5 | L9: =IF($P$8=$P$7*($P$7-1)/2,GEOMEAN(C9:K9),"") -> 0.77642616 | M9: =IF($P$8=$P$7*($P$7-1)/2,L9/SUM($L$7:$L$15),"") -> 0.083530637 | O9: λmax | P9: =IF($P$8=$P$7*($P$7-1)/2,SUMPRODUCT(C16:K16,C17:K17),"") -> 9.0266115 | Q9: م۳ | U9: =IF(AND(ISNUMBER(F9),ISNUMBER($M9),ISNUMBER($M10)),MAX(F9*$M10/$M9,$M9/(F9*$M10)),"") -> 1.0449921 | V9: =IF(AND(ISNUMBER(G9),ISNUMBER($M9),ISNUMBER($M11)),MAX(G9*$M11/$M9,$M9/(G9*$M11)),"") -> 1.1924826 | W9: =IF(AND(ISNUMBER(H9),ISNUMBER($M9),ISNUMBER($M12)),MAX(H9*$M12/$M9,$M9/(H9*$M12)),"") -> 1.0449921 | X9: =IF(AND(ISNUMBER(I9),ISNUMBER($M9),ISNUMBER($M13)),MAX(I9*$M13/$M9,$M9/(I9*$M13)),"") -> 1.0363489 | Y9: =IF(AND(ISNUMBER(J9),ISNUMBER($M9),ISNUMBER($M14)),MAX(J9*$M14/$M9,$M9/(J9*$M14)),"") -> 1.0449921 | Z9: =IF(AND(ISNUMBER(K9),ISNUMBER($M9),ISNUMBER($M15)),MAX(K9*$M15/$M9,$M9/(K9*$M15)),"") -> 1.0800597 | AA9: =IF(COUNT(R9:Z9)=0,"",MAX(R9:Z9)) -> 1.1924826
A10: م۴ | B10: ضعف در برنامه‌ریزی، پیش‌بینی و مدیریت فروش | C10: =IF(ISNUMBER(F7),1/F7,"") -> 0.6729501 | D10: =IF(ISNUMBER(F8),1/F8,"") -> 1.1040895 | E10: =IF(ISNUMBER(F9),1/F9,"") -> 1 | F10: 1 | G10: =نسبت!N30 -> 0.74299714 | H10: =نسبت!N31 -> 0.55204476 | I10: =نسبت!N32 -> 0.6729501 | J10: =نسبت!N33 -> 0.6729501 | K10: =نسبت!N34 -> 0.5 | L10: =IF($P$8=$P$7*($P$7-1)/2,GEOMEAN(C10:K10),"") -> 0.74299714 | M10: =IF($P$8=$P$7*($P$7-1)/2,L10/SUM($L$7:$L$15),"") -> 0.079934227 | O10: CI = (λmax − n) / (n − 1) | P10: =IF(ISNUMBER(P9),(P9-$P$7)/($P$7-1),"") -> 0.0033264382 | Q10: م۴ | V10: =IF(AND(ISNUMBER(G10),ISNUMBER($M10),ISNUMBER($M11)),MAX(G10*$M11/$M10,$M10/(G10*$M11)),"") -> 1.0222486 | W10: =IF(AND(ISNUMBER(H10),ISNUMBER($M10),ISNUMBER($M12)),MAX(H10*$M12/$M10,$M10/(H10*$M12)),"") -> 1.1163041 | X10: =IF(AND(ISNUMBER(I10),ISNUMBER($M10),ISNUMBER($M13)),MAX(I10*$M13/$M10,$M10/(I10*$M13)),"") -> 1.1132977 | Y10: =IF(AND(ISNUMBER(J10),ISNUMBER($M10),ISNUMBER($M14)),MAX(J10*$M14/$M10,$M10/(J10*$M14)),"") -> 1.0110631 | Z10: =IF(AND(ISNUMBER(K10),ISNUMBER($M10),ISNUMBER($M15)),MAX(K10*$M15/$M10,$M10/(K10*$M15)),"") -> 1.0335578 | AA10: =IF(COUNT(R10:Z10)=0,"",MAX(R10:Z10)) -> 1.1163041
A11: م۵ | B11: ناکارآمدی و هزینه‌بری شبکه توزیع و فروش | C11: =IF(ISNUMBER(G7),1/G7,"") -> 0.90572366 | D11: =IF(ISNUMBER(G8),1/G8,"") -> 1.8114473 | E11: =IF(ISNUMBER(G9),1/G9,"") -> 1.1040895 | F11: =IF(ISNUMBER(G10),1/G10,"") -> 1.3459002 | G11: 1 | H11: =نسبت!N35 -> 1 | I11: =نسبت!N36 -> 0.74299714 | J11: =نسبت!N37 -> 1 | K11: =نسبت!N38 -> 0.6729501 | L11: =IF($P$8=$P$7*($P$7-1)/2,GEOMEAN(C11:K11),"") -> 1.0222486 | M11: =IF($P$8=$P$7*($P$7-1)/2,L11/SUM($L$7:$L$15),"") -> 0.10997707 | O11: RI (Saaty) | P11: =INDEX(راهنما!$C$29:$C$38,MATCH($P$7,راهنما!$B$29:$B$38,0)) -> 1.45 | Q11: م۵ | W11: =IF(AND(ISNUMBER(H11),ISNUMBER($M11),ISNUMBER($M12)),MAX(H11*$M12/$M11,$M11/(H11*$M12)),"") -> 1.1794344 | X11: =IF(AND(ISNUMBER(I11),ISNUMBER($M11),ISNUMBER($M13)),MAX(I11*$M13/$M11,$M11/(I11*$M13)),"") -> 1.1193187 | Y11: =IF(AND(ISNUMBER(J11),ISNUMBER($M11),ISNUMBER($M14)),MAX(J11*$M14/$M11,$M11/(J11*$M14)),"") -> 1.0682417 | Z11: =IF(AND(ISNUMBER(K11),ISNUMBER($M11),ISNUMBER($M15)),MAX(K11*$M15/$M11,$M11/(K11*$M15)),"") -> 1.056553 | AA11: =IF(COUNT(R11:Z11)=0,"",MAX(R11:Z11)) -> 1.1794344
A12: م۶ | B12: شدت رقابت و فشار قیمتی بازار | C12: =IF(ISNUMBER(H7),1/H7,"") -> 1 | D12: =IF(ISNUMBER(H8),1/H8,"") -> 2 | E12: =IF(ISNUMBER(H9),1/H9,"") -> 1.4859943 | F12: =IF(ISNUMBER(H10),1/H10,"") -> 1.8114473 | G12: =IF(ISNUMBER(H11),1/H11,"") -> 1 | H12: 1 | I12: =نسبت!N39 -> 1 | J12: =نسبت!N40 -> 1 | K12: =نسبت!N41 -> 1 | L12: =IF($P$8=$P$7*($P$7-1)/2,GEOMEAN(C12:K12),"") -> 1.2056752 | M12: =IF($P$8=$P$7*($P$7-1)/2,L12/SUM($L$7:$L$15),"") -> 0.12971074 | O12: CR = CI / RI | P12: =IF(ISNUMBER(P10),IF(P11=0,0,MAX(0,P10)/P11),"") -> 0.0022940953 | Q12: م۶ | X12: =IF(AND(ISNUMBER(I12),ISNUMBER($M12),ISNUMBER($M13)),MAX(I12*$M13/$M12,$M12/(I12*$M13)),"") -> 1.0194955 | Y12: =IF(AND(ISNUMBER(J12),ISNUMBER($M12),ISNUMBER($M14)),MAX(J12*$M14/$M12,$M12/(J12*$M14)),"") -> 1.1040895 | Z12: =IF(AND(ISNUMBER(K12),ISNUMBER($M12),ISNUMBER($M15)),MAX(K12*$M15/$M12,$M12/(K12*$M15)),"") -> 1.1924826 | AA12: =IF(COUNT(R12:Z12)=0,"",MAX(R12:Z12)) -> 1.1924826
A13: م۷ | B13: تغییر ذائقه مصرف‌کننده و محدودیت بازار هدف | C13: =IF(ISNUMBER(I7),1/I7,"") -> 1 | D13: =IF(ISNUMBER(I8),1/I8,"") -> 2.1552289 | E13: =IF(ISNUMBER(I9),1/I9,"") -> 1.6406707 | F13: =IF(ISNUMBER(I10),1/I10,"") -> 1.4859943 | G13: =IF(ISNUMBER(I11),1/I11,"") -> 1.3459002 | H13: =IF(ISNUMBER(I12),1/I12,"") -> 1 | I13: 1 | J13: =نسبت!N42 -> 1.1040895 | K13: =نسبت!N43 -> 0.82033536 | L13: =IF($P$8=$P$7*($P$7-1)/2,GEOMEAN(C13:K13),"") -> 1.2291804 | M13: =IF($P$8=$P$7*($P$7-1)/2,L13/SUM($L$7:$L$15),"") -> 0.13223952 | O13: وضعیت | P13: =IF(NOT($P$8=$P$7*($P$7-1)/2),"ناقص",IF(P12<=$P$3,"سازگار","ناسازگار")) -> سازگار | Q13: م۷ | Y13: =IF(AND(ISNUMBER(J13),ISNUMBER($M13),ISNUMBER($M14)),MAX(J13*$M14/$M13,$M13/(J13*$M14)),"") -> 1.0194955 | Z13: =IF(AND(ISNUMBER(K13),ISNUMBER($M13),ISNUMBER($M15)),MAX(K13*$M15/$M13,$M13/(K13*$M15)),"") -> 1.0421778 | AA13: =IF(COUNT(R13:Z13)=0,"",MAX(R13:Z13)) -> 1.0421778
A14: م۸ | B14: ناپایداری تأمین و نوسان بهای مواد اولیه | C14: =IF(ISNUMBER(J7),1/J7,"") -> 0.90572366 | D14: =IF(ISNUMBER(J8),1/J8,"") -> 1.8114473 | E14: =IF(ISNUMBER(J9),1/J9,"") -> 1.3459002 | F14: =IF(ISNUMBER(J10),1/J10,"") -> 1.4859943 | G14: =IF(ISNUMBER(J11),1/J11,"") -> 1 | H14: =IF(ISNUMBER(J12),1/J12,"") -> 1 | I14: =IF(ISNUMBER(J13),1/J13,"") -> 0.90572366 | J14: 1 | K14: =نسبت!N44 -> 0.74299714 | L14: =IF($P$8=$P$7*($P$7-1)/2,GEOMEAN(C14:K14),"") -> 1.0920085 | M14: =IF($P$8=$P$7*($P$7-1)/2,L14/SUM($L$7:$L$15),"") -> 0.11748209 | O14: بیشترین انحراف یک مقایسه | P14: =IF(COUNT(AA7:AA15)=0,"",MAX(AA7:AA15)) -> 1.1924826 | Q14: م۸ | Z14: =IF(AND(ISNUMBER(K14),ISNUMBER($M14),ISNUMBER($M15)),MAX(K14*$M15/$M14,$M14/(K14*$M15)),"") -> 1.0222486 | AA14: =IF(COUNT(R14:Z14)=0,"",MAX(R14:Z14)) -> 1.0222486
A15: م۹ | B15: فشارهای اقتصاد کلان و کاهش قدرت خرید | C15: =IF(ISNUMBER(K7),1/K7,"") -> 1.3459002 | D15: =IF(ISNUMBER(K8),1/K8,"") -> 2 | E15: =IF(ISNUMBER(K9),1/K9,"") -> 2 | F15: =IF(ISNUMBER(K10),1/K10,"") -> 2 | G15: =IF(ISNUMBER(K11),1/K11,"") -> 1.4859943 | H15: =IF(ISNUMBER(K12),1/K12,"") -> 1 | I15: =IF(ISNUMBER(K13),1/K13,"") -> 1.2190137 | J15: =IF(ISNUMBER(K14),1/K14,"") -> 1.3459002 | K15: 1 | L15: =IF($P$8=$P$7*($P$7-1)/2,GEOMEAN(C15:K15),"") -> 1.4377467 | M15: =IF($P$8=$P$7*($P$7-1)/2,L15/SUM($L$7:$L$15),"") -> 0.15467781 | O15: مقایسهٔ دارای بیشترین انحراف | P15: =IF(ISNUMBER(P14),INDEX(A7:A15,MATCH(P14,AA7:AA15,0))&" و "&INDEX(C6:K6,MATCH(P14,INDEX(R7:Z15,MATCH(P14,AA7:AA15,0),0),0)),"") -> م۳ و م۵ | Q15: م۹
B16: مجموع ستون | C16: =IF($P$8=$P$7*($P$7-1)/2,SUM(C7:C15),"") -> 8.0242245 | D16: =IF($P$8=$P$7*($P$7-1)/2,SUM(D7:D15),"") -> 14.905774 | E16: =IF($P$8=$P$7*($P$7-1)/2,SUM(E7:E15),"") -> 11.968373 | F16: =IF($P$8=$P$7*($P$7-1)/2,SUM(F7:F15),"") -> 12.521054 | G16: =IF($P$8=$P$7*($P$7-1)/2,SUM(G7:G15),"") -> 9.1367496 | H16: =IF($P$8=$P$7*($P$7-1)/2,SUM(H7:H15),"") -> 7.7249949 | I16: =IF($P$8=$P$7*($P$7-1)/2,SUM(I7:I15),"") -> 7.6141792 | J16: =IF($P$8=$P$7*($P$7-1)/2,SUM(J7:J15),"") -> 8.5220712 | K16: =IF($P$8=$P$7*($P$7-1)/2,SUM(K7:K15),"") -> 6.4792797 | M16: =IF($P$8=$P$7*($P$7-1)/2,SUM(M7:M15),"") -> 1
B17: وزن (برای محاسبهٔ λmax) | C17: =M7 -> 0.1249275 | D17: =M8 -> 0.067520412 | E17: =M9 -> 0.083530637 | F17: =M10 -> 0.079934227 | G17: =M11 -> 0.10997707 | H17: =M12 -> 0.12971074 | I17: =M13 -> 0.13223952 | J17: =M14 -> 0.11748209 | K17: =M15 -> 0.15467781
A19: گویه‌های مؤلفهٔ م۱: آسیب‌پذیری ساختاری ناشی از تمرکز بر محصول واحد (۳×۳) | Q19: انحراف هر مقایسه از وزن‌های برآوردشده (۱ = کاملاً سازگار)
A20: کد | B20: مورد | C20: گ۱ | D20: گ۲ | E20: گ۳ | L20: میانگین هندسی سطر | M20: وزن | Q20: کد | R20: گ۱ | S20: گ۲ | T20: گ۳ | AA20: بیشینهٔ سطر
A21: گ۱ | B21: وابستگی کامل درآمد و سودآوری شرکت به تقاضای یک محصول | C21: 1 | D21: =نسبت!N45 -> 1 | E21: =نسبت!N46 -> 1.3459002 | L21: =IF($P$22=$P$21*($P$21-1)/2,GEOMEAN(C21:E21),"") -> 1.1040895 | M21: =IF($P$22=$P$21*($P$21-1)/2,L21/SUM($L$21:$L$23),"") -> 0.36456473 | O21: تعداد گزینه‌ها (n) | P21: =ROWS(A21:A23) -> 3 | Q21: گ۱ | S21: =IF(AND(ISNUMBER(D21),ISNUMBER($M21),ISNUMBER($M22)),MAX(D21*$M22/$M21,$M21/(D21*$M22)),"") -> 1 | T21: =IF(AND(ISNUMBER(E21),ISNUMBER($M21),ISNUMBER($M23)),MAX(E21*$M23/$M21,$M21/(E21*$M23)),"") -> 1 | AA21: =IF(COUNT(R21:T21)=0,"",MAX(R21:T21)) -> 1
A22: گ۲ | B22: نبود امکان جبران افت فروش از محل سایر اقلام سبد محصول | C22: =IF(ISNUMBER(D21),1/D21,"") -> 1 | D22: 1 | E22: =نسبت!N47 -> 1.3459002 | L22: =IF($P$22=$P$21*($P$21-1)/2,GEOMEAN(C22:E22),"") -> 1.1040895 | M22: =IF($P$22=$P$21*($P$21-1)/2,L22/SUM($L$21:$L$23),"") -> 0.36456473 | O22: مقایسه‌های ثبت‌شده | P22: =(COUNT(C21:E23)-$P$21)/2 -> 3 | Q22: گ۲ | T22: =IF(AND(ISNUMBER(E22),ISNUMBER($M22),ISNUMBER($M23)),MAX(E22*$M23/$M22,$M22/(E22*$M23)),"") -> 1 | AA22: =IF(COUNT(R22:T22)=0,"",MAX(R22:T22)) -> 1
A23: گ۳ | B23: کاهش انعطاف‌پذیری و کندی واکنش شرکت به تغییرات بازار | C23: =IF(ISNUMBER(E21),1/E21,"") -> 0.74299714 | D23: =IF(ISNUMBER(E22),1/E22,"") -> 0.74299714 | E23: 1 | L23: =IF($P$22=$P$21*($P$21-1)/2,GEOMEAN(C23:E23),"") -> 0.82033536 | M23: =IF($P$22=$P$21*($P$21-1)/2,L23/SUM($L$21:$L$23),"") -> 0.27087055 | O23: λmax | P23: =IF($P$22=$P$21*($P$21-1)/2,SUMPRODUCT(C24:E24,C25:E25),"") -> 3 | Q23: گ۳
B24: مجموع ستون | C24: =IF($P$22=$P$21*($P$21-1)/2,SUM(C21:C23),"") -> 2.7429971 | D24: =IF($P$22=$P$21*($P$21-1)/2,SUM(D21:D23),"") -> 2.7429971 | E24: =IF($P$22=$P$21*($P$21-1)/2,SUM(E21:E23),"") -> 3.6918004 | M24: =IF($P$22=$P$21*($P$21-1)/2,SUM(M21:M23),"") -> 1 | O24: CI = (λmax − n) / (n − 1) | P24: =IF(ISNUMBER(P23),(P23-$P$21)/($P$21-1),"") -> 0
B25: وزن (برای محاسبهٔ λmax) | C25: =M21 -> 0.36456473 | D25: =M22 -> 0.36456473 | E25: =M23 -> 0.27087055 | O25: RI (Saaty) | P25: =INDEX(راهنما!$C$29:$C$38,MATCH($P$21,راهنما!$B$29:$B$38,0)) -> 0.58
O26: CR = CI / RI | P26: =IF(ISNUMBER(P24),IF(P25=0,0,MAX(0,P24)/P25),"") -> 0
O27: وضعیت | P27: =IF(NOT($P$22=$P$21*($P$21-1)/2),"ناقص",IF(P26<=$P$3,"سازگار","ناسازگار")) -> سازگار
O28: بیشترین انحراف یک مقایسه | P28: =IF(COUNT(AA21:AA23)=0,"",MAX(AA21:AA23)) -> 1
O29: مقایسهٔ دارای بیشترین انحراف | P29: =IF(ISNUMBER(P28),INDEX(A21:A23,MATCH(P28,AA21:AA23,0))&" و "&INDEX(C20:E20,MATCH(P28,INDEX(R21:T23,MATCH(P28,AA21:AA23,0),0),0)),"") -> گ۱ و گ۲
A31: گویه‌های مؤلفهٔ م۲: ضعف برندسازی و دشواری تمایز محصول (۴×۴) | Q31: انحراف هر مقایسه از وزن‌های برآوردشده (۱ = کاملاً سازگار)
A32: کد | B32: مورد | C32: گ۴ | D32: گ۵ | E32: گ۶ | F32: گ۷ | L32: میانگین هندسی سطر | M32: وزن | Q32: کد | R32: گ۴ | S32: گ۵ | T32: گ۶ | U32: گ۷ | AA32: بیشینهٔ سطر
A33: گ۴ | B33: ضعف در برندسازی و تبلیغات و کمرنگ بودن جایگاه برند در ذهن مشتری | C33: 1 | D33: =نسبت!N48 -> 1 | E33: =نسبت!N49 -> 1.8114473 | F33: =نسبت!N50 -> 1.8114473 | L33: =IF($P$34=$P$33*($P$33-1)/2,GEOMEAN(C33:F33),"") -> 1.3459002 | M33: =IF($P$34=$P$33*($P$33-1)/2,L33/SUM($L$33:$L$36),"") -> 0.32215566 | O33: تعداد گزینه‌ها (n) | P33: =ROWS(A33:A36) -> 4 | Q33: گ۴ | S33: =IF(AND(ISNUMBER(D33),ISNUMBER($M33),ISNUMBER($M34)),MAX(D33*$M34/$M33,$M33/(D33*$M34)),"") -> 1 | T33: =IF(AND(ISNUMBER(E33),ISNUMBER($M33),ISNUMBER($M35)),MAX(E33*$M35/$M33,$M33/(E33*$M35)),"") -> 1 | U33: =IF(AND(ISNUMBER(F33),ISNUMBER($M33),ISNUMBER($M36)),MAX(F33*$M36/$M33,$M33/(F33*$M36)),"") -> 1 | AA33: =IF(COUNT(R33:U33)=0,"",MAX(R33:U33)) -> 1
A34: گ۵ | B34: دشواری ایجاد تمایز نسبت به محصولات رقیب | C34: =IF(ISNUMBER(D33),1/D33,"") -> 1 | D34: 1 | E34: =نسبت!N51 -> 1.8114473 | F34: =نسبت!N52 -> 1.8114473 | L34: =IF($P$34=$P$33*($P$33-1)/2,GEOMEAN(C34:F34),"") -> 1.3459002 | M34: =IF($P$34=$P$33*($P$33-1)/2,L34/SUM($L$33:$L$36),"") -> 0.32215566 | O34: مقایسه‌های ثبت‌شده | P34: =(COUNT(C33:F36)-$P$33)/2 -> 6 | Q34: گ۵ | T34: =IF(AND(ISNUMBER(E34),ISNUMBER($M34),ISNUMBER($M35)),MAX(E34*$M35/$M34,$M34/(E34*$M35)),"") -> 1 | U34: =IF(AND(ISNUMBER(F34),ISNUMBER($M34),ISNUMBER($M36)),MAX(F34*$M36/$M34,$M34/(F34*$M36)),"") -> 1 | AA34: =IF(COUNT(R34:U34)=0,"",MAX(R34:U34)) -> 1
A35: گ۶ | B35: نبود نوآوری و توسعه محصول | C35: =IF(ISNUMBER(E33),1/E33,"") -> 0.55204476 | D35: =IF(ISNUMBER(E34),1/E34,"") -> 0.55204476 | E35: 1 | F35: =نسبت!N53 -> 1 | L35: =IF($P$34=$P$33*($P$33-1)/2,GEOMEAN(C35:F35),"") -> 0.74299714 | M35: =IF($P$34=$P$33*($P$33-1)/2,L35/SUM($L$33:$L$36),"") -> 0.17784434 | O35: λmax | P35: =IF($P$34=$P$33*($P$33-1)/2,SUMPRODUCT(C37:F37,C38:F38),"") -> 4 | Q35: گ۶ | U35: =IF(AND(ISNUMBER(F35),ISNUMBER($M35),ISNUMBER($M36)),MAX(F35*$M36/$M35,$M35/(F35*$M36)),"") -> 1 | AA35: =IF(COUNT(R35:U35)=0,"",MAX(R35:U35)) -> 1
A36: گ۷ | B36: کم‌توجهی به تحقیقات بازار و مطالعه رفتار مصرف‌کننده | C36: =IF(ISNUMBER(F33),1/F33,"") -> 0.55204476 | D36: =IF(ISNUMBER(F34),1/F34,"") -> 0.55204476 | E36: =IF(ISNUMBER(F35),1/F35,"") -> 1 | F36: 1 | L36: =IF($P$34=$P$33*($P$33-1)/2,GEOMEAN(C36:F36),"") -> 0.74299714 | M36: =IF($P$34=$P$33*($P$33-1)/2,L36/SUM($L$33:$L$36),"") -> 0.17784434 | O36: CI = (λmax − n) / (n − 1) | P36: =IF(ISNUMBER(P35),(P35-$P$33)/($P$33-1),"") -> 0 | Q36: گ۷
B37: مجموع ستون | C37: =IF($P$34=$P$33*($P$33-1)/2,SUM(C33:C36),"") -> 3.1040895 | D37: =IF($P$34=$P$33*($P$33-1)/2,SUM(D33:D36),"") -> 3.1040895 | E37: =IF($P$34=$P$33*($P$33-1)/2,SUM(E33:E36),"") -> 5.6228947 | F37: =IF($P$34=$P$33*($P$33-1)/2,SUM(F33:F36),"") -> 5.6228947 | M37: =IF($P$34=$P$33*($P$33-1)/2,SUM(M33:M36),"") -> 1 | O37: RI (Saaty) | P37: =INDEX(راهنما!$C$29:$C$38,MATCH($P$33,راهنما!$B$29:$B$38,0)) -> 0.9
B38: وزن (برای محاسبهٔ λmax) | C38: =M33 -> 0.32215566 | D38: =M34 -> 0.32215566 | E38: =M35 -> 0.17784434 | F38: =M36 -> 0.17784434 | O38: CR = CI / RI | P38: =IF(ISNUMBER(P36),IF(P37=0,0,MAX(0,P36)/P37),"") -> 0
